Workbook

Sheet 00 Executive Summary
A1: RECORDATI (BIT: REC) — INDEPENDENT LBO, EXECUTIVE SUMMARY | v4, 03 SEP 2026 (financing structure per CONSOB offer doc)
A3: THE ANSWER
A4: Base-case IRR (5yr, 11.5x exit): | B4: ='10 Returns'!B11 -> 0.22324524
A5: Base-case MOIC: | B5: ='10 Returns'!B9 -> 2.7388463
A6: Entry: 12.6x on close-date net debt / structure per CONSOB offer doc: ~44% equity (EUR4.5bn) / ~41% Bridge-Senior / ~15% PIK Notes (live 06!B12:B22)
A7: Sponsor equity (model): | B7: ='06 Sources & Uses'!B18 -> 4524.7511
A8: Debt paydown over hold (gross): | B8: ='06 Sources & Uses'!B13-'08 Debt Schedule'!K17 -> 1335.6004
A10: WHAT DRIVES THE RETURN
A11: 1. EBITDA growth: organic RD (+14%->9%) + SPC (+2%) to ~EUR 1.46bn by 2031; BD EUR 400m/yr 2027-2030 (exit-yr spend removed; cum. EUR 1.6bn) adds ~EUR 178m acquired EBITDA at 9.0x effective -> ~EUR 1.6bn total.
A12: 2. Deleveraging: cash sweep pays down Bridge/Senior Facilities; PIK Notes accrue (non-cash) and are repaid at exit -- leverage trajectory now live in 08 Debt Schedule (v4 structure, not the old TLB estimate).
A13: 3. Exit multiple: base 11.5x (COMPRESSION vs 12.9x entry). ~2.0-2.5pts IRR per turn. Rossini precedent: 0 expansion over 8 yrs.
A15: KEY ASSUMPTIONS (speed-read)
A16: RD growth y1-3 / y4-5 | B16: ='03 Assumptions'!F6 -> 0.14
A17: SPC growth | B17: ='03 Assumptions'!F8 -> 0.02
A18: Margin path 36.5% → | B18: ='03 Assumptions'!F9 -> 0.3775
A19: Leverage (total debt / FY25A EBITDA, per disclosed structure) | B19: ='06 Sources & Uses'!B13/'03 Assumptions'!B16 -> 8.0969821
A20: Exit multiple | B20: ='03 Assumptions'!F11 -> 11.5
A21: Bridge/Senior rate ~5.85%, PIK ~8.6% (both ESTIMATES -- offer doc does not disclose margins); tax 24%; maint. capex 1.75% rev
A23: RECOMMENDED ACTION
A24: PARTICIPATE selectively (co-invest): V3 base ~15% IRR / ~2.0x MOIC (live 00!B4:B5). No-BD conservative floor ~15% (F13=0) — funding BD is
A25: roughly IRR-NEUTRAL: the 9x-in / 11.5x-out arbitrage is almost exactly offset by interest drag on un-swept cash + forfeited deleveraging. The
A26: sponsor-consistent ~18% case is exit-multiple MAINTENANCE (entry-flat 12.9x = +2.9pt), NOT BD arbitrage. Bull (BD+12.9x+6.0x lev) ~24%/3.0x. Clears a co-invest bar, not a 20% standalone hurdle.
A28: KEY RISKS (ranked)
A29: 1. Exit multiple compression toward Ipsen 8.4x: at 10x exit, IRR falls to single digits — dominant risk.
A30: 2. Isturisa vs Corcept relacorilant: RD growth engine concentration (~35-40% of RD est.).
A31: 3. FY26 margin guide-down proves structural (not investment/FX): EBITDA base erodes.
A32: 4. US policy (IRA/tariffs) on the RD growth market; SPC decay acceleration (Turkey/Russia).
A33: 5. Seller = best-informed party (CVC VII → IX continuation): adverse-selection discount warranted.
A35: HOW TO USE: scenario switch '03 Assumptions'!B3; BLUE=input, BLACK=formula, GREEN=link, RED=check; yellow=key levers.
A37: GLOSSARY
A38: IRR / MOIC | C38: Internal rate of return / Multiple of invested capital (exit equity ÷ entry equity)
A39: Bridge/Senior / PIK / RCF | C39: Bridge & Senior Facilities (cash-pay, sweepable) / PIK Notes (accrue, non-cash, paid at exit) / Revolving Credit Facility -- see 06 Sources & Uses for the disclosed CONSOB split
A40: Cash sweep | C40: Excess FCF mandatorily prepays the Bridge/Senior Facilities; PIK Notes are not swept
A41: OID | C41: Original issue discount — financing fee reducing net debt proceeds, capitalised
A42: DSCR / Coverage | C42: Debt service coverage ratio / EBITDA ÷ cash interest — financeability tests
A43: S&U | C43: Sources & Uses — where the money comes from and goes at close
B45: 2029 | C45: 2030 | D45: 2031
A46: IRR by exit year (live): | B46: ='10 Returns'!B27 -> 0.23404878 | C46: ='10 Returns'!C27 -> 0.22427379 | D46: ='10 Returns'!D27 -> 0.22324524

Sheet 01 Cover
A1: RECORDATI S.p.A. (BIT: REC) — INDEPENDENT LBO MODEL
A3: Investment question: could an outside investor independently justify the €10.7bn take-private by CVC Fund IX & GBL?
A4: Built BLIND to the sponsors' model, then compared against the actual announced transaction (see 13 Dashboard).
A6: Prepared 17-Jul-2026 | Analyst: Tanmay Gambhir | €m | Entry: close 31-Dec-26 | Exit: 31-Dec-31 (base)
A8: Color code: BLUE input | BLACK formula | GREEN cross-sheet | RED check. Yellow = primary levers.
A9: Scenario switch: '03 Assumptions'!B3 (1=Bear, 2=Base, 3=Bull).
A11: 00 Executive Summary — answer first
A12: 02 Sources
A13: 03 Assumptions
A14: 04 Historical Financials
A15: 05 Transaction Overview
A16: 06 Sources & Uses
... A23: 13 Dashboard + actual-deal comparison

Sheet 03 Assumptions
A1: ASSUMPTIONS & SCENARIO SWITCH — all inputs blue
A3: SCENARIO SWITCH (1=Bear, 2=Base, 3=Bull) | B3: 2 | C3: =IF(OR(B3=1,B3=2,B3=3),"OK","ERROR: 1/2/3 only") -> OK
A5: Scenario inputs | C5: Bear | D5: Base | E5: Bull | F5: ACTIVE
A6: Rare Diseases growth 2027-29 | C6: 0.08 | D6: 0.14 | E6: 0.19 | F6: =CHOOSE($B$3,C6,D6,E6) -> 0.14
A7: Rare Diseases growth 2030-31 | C7: 0.05 | D7: 0.09 | E7: 0.12 | F7: =CHOOSE($B$3,C7,D7,E7) -> 0.09
A8: Specialty & Primary Care growth p.a. | C8: -0.01 | D8: 0.02 | E8: 0.035 | F8: =CHOOSE($B$3,C8,D8,E8) -> 0.02
A9: EBITDA margin endpoint (by 2029) | C9: 0.36 | D9: 0.3775 | E9: 0.39 | F9: =CHOOSE($B$3,C9,D9,E9) -> 0.3775
A10: Entry leverage (x FY25 EBITDA €991m) | C10: 5 | D10: 5.5 | E10: 6 | F10: =CHOOSE($B$3,C10,D10,E10) -> 5.5
A11: Exit EV/EBITDA multiple | C11: 10 | D11: 11.5 | E11: 12.9 | F11: =CHOOSE($B$3,C11,D11,E11) -> 11.5
A12: Cash sweep % of excess FCF | C12: 1 | D12: 1 | E12: 1 | F12: =CHOOSE($B$3,C12,D12,E12) -> 1
A13: BD / in-licensing spend per year 2027-31 (EUR m) | C13: 0 | D13: 400 | E13: 600 | F13: =CHOOSE($B$3,C13,D13,E13) -> 400
A15: Fixed inputs
A16: FY2025A EBITDA (company-adj, €m) | B16: 991.1
A17: FY2025A revenue (€m) | B17: 2618.4
A18: FY2025A Rare Diseases revenue | B18: 1081.4
A19: FY2025A SPC revenue | B19: 1537
A20: Offer price €/share (ex-div) | B20: 51.29
A21: Shares (m) | B21: 209.125
A22: Equity purchase price (Max Disbursement Amount, disclosed shares x price) | B22: =B57*B20 -> 10182.376
A23: Existing net debt refinanced (close-date est., =B52) | B23: =B52 -> 1767.3
A24: Advisory/other fees % of EV | B24: 0.0125
A25: OID & financing fees % of new debt | B25: 0.025
A26: Euribor (3M, assumed) | B26: 0.021
A27: TLB-EUR spread | B27: 0.0375
A28: TLB-USD all-in rate | B28: 0.0725
A29: Senior Secured Notes coupon | B29: 0.0675
A30: RCF size (undrawn, €m) | B30: 500
A31: RCF commitment fee | B31: 0.004
A32: Maintenance capex % revenue | B32: 0.0175
A33: D&A % revenue | B33: 0.079
A34: Cash tax rate | B34: 0.24
A35: Change in NWC % of revenue change | B35: 0.15
... A45: ATAD interest deduction cap (% of EBITDA) | B45: 0.3
A47: v2: BASE now FUNDS BD (EUR 400m/yr at 9.0x, pre-sweep) per IC direction. Set F13=0 for the conservative no-BD floor.
A48: v2: taxes apply the ATAD 30%-of-EBITDA interest deduction cap; EUR 250m minimum cash funded at close; fees 1.25% EV.
A49: FY25A net debt, gross (announced-deal basis) | B49: 2037.3
A50: (-) 2026E FCF generated pre-close | B50: -550
A51: (+) 2026E dividends paid | B51: 280
A52: Est. net debt at Q4-26 close (L-confidence) | B52: =B49+B50+B51 -> 1767.3
A54: v3: net debt refinanced now uses close-date estimate (B52), not FY25A gross (B49). Lowers uses/equity check & entry EV.
...

Sheet 02 Sources
A1: SOURCE REGISTER
A3: Item | B3: Value | C3: Conf. | D3: Source / date
A4: Offer terms | B4: €51.29 ex-div (€52.00 cum); 209,125,156 sh; €10,726.0m | C4: H | D4: Offeror PR (CVC IX & GBL via Respighi BidCo), 22-May-2026
A5: Premium | B5: 12.89% vs undisturbed 25-Mar-26 | C5: H | D5: Offeror PR
A6: FY25 revenue / EBITDA / net debt | B6: 2,618.4 / 991.1 / 2,037.3 | C6: H | D6: Recordati FY25 PR 17-Feb-26; accounts approved 19-Mar-26
A7: FY26 guidance | B7: Rev 2,730-2,800; EBITDA 995-1,030 (36.5%) | C7: H | D7: FY25 PR
A8: Segment FY25 | B8: RD 1,081.4 (+29.7%); SPC ~1,537 derived | C8: H/M | D8: FY25 PR / derived
A9: Historicals 2021-25 | B9: see 04 | C9: H | D9: stockanalysis.com (Fiscal.ai), May-26; EBITDA definition note on 04
A10: Debt package (actual deal) | B10: ~€5.5-6.0bn sought; up to €8bn pitched | C10: M | D10: Bloomberg 17-Apr-26
A11: Debt pricing assumptions | B11: TLB E+375; USD 7.25%; SSN 6.75%; OID 2.5% | C11: L/M | D11: Market convention; Euribor 2.1% assumed (refresh at close)
A12: Rossini 2018 entry | B12: €28.00/sh; 12.9x 2017 EBITDA; €3.03bn for 51.8% | C12: H | D12: Unquote/CVC PR 2018
A13: Isturisa peak sales | B13: >€1.2bn (doubled Nov-25) | C13: H | D13: Recordati 9M-25 PR 11-Nov-25
A14: Maintenance capex / tax | B14: 1.5-2.0% rev / 24% | C14: H | D14: Fiscal.ai 2021-25: capex 22-39m, ETR 20.7-23.9%
A15: Structure & scenario paths | B15: 03 Assumptions | C15: L/M | D15: Analyst judgment; see project Assumptions Register
A18: Page citations: offer terms — Offeror PR pp.1-2; FY25 figures — FY25 PR headline table; segments — FY25/Q1-25 PRs.
A19: No annotated screenshots (environment limitation); citations are table-level and PDFs are linked in the project Bibliography.

Sheet 04 Historical Financials
A1: HISTORICAL FINANCIALS 2021-2025
A3: €m | B3: 2021 | C3: 2022 | D3: 2023 | E3: 2024 | F3: 2025
A4: Revenue | B4: 1580 | C4: 1853 | D4: 2082 | E4: 2342 | F4: 2618.4
A5: Company-adj. EBITDA | B5: 588 | C5: 692 | D5: 770 | E5: 865.8 | F5: 991.1
A6: R&D expense | B6: 166 | C6: 220 | D6: 256 | E6: 286 | F6: 341
A7: Operating cash flow | B7: 492 | C7: 462 | D7: 485 | E7: 570 | F7: 597
A8: PP&E capex | B8: 22 | C8: 24 | D8: 30 | E8: 37 | F8: 39
A9: FCF (OCF - capex) | B9: 470 | C9: 438 | D9: 456 | E9: 533 | F9: 557
A10: Intangibles purchased (BD/in-licensing) | B10: 66 | C10: 72 | D10: 354 | E10: 815 | F10: 46
A11: DPS (€) | B11: 1.1 | C11: 1.15 | D11: 1.2 | E11: 1.27 | F11: 1.34
A12: Effective tax rate | B12: 0.167 | C12: 0.222 | D12: 0.207 | E12: 0.239 | F12: 0.237
A13: Net debt (year-end) | E13: 1875 | F13: 2037.3
A15: EBITDA margin | B15: =B5/B4 -> 0.3721519 | C15: =C5/C4 -> 0.37344846 | D15: =D5/D4 -> 0.3698367 | E15: =E5/E4 -> 0.36968403 | F15: =F5/F4 -> 0.3785136
A16: Revenue growth | C16: =C4/B4-1 -> 0.17278481 | D16: =D4/C4-1 -> 0.12358338 | E16: =E4/D4-1 -> 0.12487992 | F16: =F4/E4-1 -> 0.11801879
A17: FCF / EBITDA conversion | B17: =B9/B5 -> 0.79931973 | C17: =C9/C5 -> 0.63294798 | D17: =D9/D5 -> 0.59220779 | E17: =E9/E5 -> 0.61561562 | F17: =F9/F5 -> 0.56200182
A19: NOTE: 2021-24 EBITDA shown uses company-adjusted definition where available; aggregator-standardised EBITDA differs
A20: (2025: 877 standardised vs 991 company-adj). Deal math throughout uses the COMPANY-ADJUSTED figure (offer-consistent).
A21: Growth engine runs through the intangibles line (Enjaymo €815m in 2024) — base case deliberately excludes BD spend.

Sheet 05 Transaction Overview
A1: TRANSACTION OVERVIEW — CVC IX & GBL / RESPIGHI BIDCO
A3: Announcement | C3: 22 May 2026 (non-binding interest 25-Mar-26)
A4: Structure | C4: Voluntary totalitarian cash tender offer; delisting from Euronext Milan
A5: Offer price | C5: €51.29 ex-div (€52.00 cum 2025 final dividend €0.71)
A6: Premium | C6: 12.89% vs undisturbed 25-Mar-26 (low: Rossini 46.82% pre-committed)
A7: Rossini | C7: CVC VII vehicle, 46.82%, irrevocably tendering — effectively CVC VII → CVC IX continuation
A8: Co-investors | C8: GBL (≤~€1.3bn), ADIA/Luxinva, CPPIB, PSP, StepStone, AlpInvest, MGG, CapSol, A. Recordati rollover
A9: Financing | C9: Fully committed; ~€5.5-6.0bn debt sought (Mediobanca, GS, Jefferies, JPM, DB)
A10: Conditions | C10: ≥66.67% acceptance; antitrust/FDI/FSR
A11: Timeline | C11: Closing expected Q4 2026; squeeze-out/merger thereafter
A12: Rationale (offeror) | C12: Private ownership for higher-risk BD/R&D phase without public-market earnings scrutiny
A15: THIS MODEL: an INDEPENDENT underwrite at the same price — sponsor economics tested blind, then reconciled (13 Dashboard).
A16: Why the market traded at EUR 46 undisturbed: FY26 margin guide-down (37.8%->36.5%), FX headwind ~-3.5%, US policy
A17: overhang and Isturisa competitive risk - i.e. the public market partially priced the risks our bear case models. The low
A18: 12.89% premium cleared because Rossini (46.82%) pre-committed; minorities had no effective blocking position.

Sheet 06 Sources & Uses
A1: SOURCES & USES (at close, 31-Dec-2026) — v4: real disclosed structure (CONSOB offer doc, 31 Aug 2026)
A3: USES (€m)
A4: Equity purchase price | B4: ='03 Assumptions'!B22 -> 10182.376
A5: Refinance existing net debt | B5: ='03 Assumptions'!B23 -> 1767.3
A6: Advisory & other fees (1.25% of EV, = 03!B24) | B6: ='03 Assumptions'!B24*('07 Purchase Price'!B7) -> 149.37095
A7: OID & financing fees (2.5% of new debt = B9-B18, closed form -- see B9 note) | B7: ='03 Assumptions'!B25*(B9-B18) -> 200.62297
A8: Minimum operating cash to balance sheet | B8: ='03 Assumptions'!B44 -> 250
A9: TOTAL USES (closed form: solves the OID circularity below algebraically) | B9: =(B4+B5+B6+B8-'03 Assumptions'!B25*B18)/(1-'03 Assumptions'!B25) -> 12549.67
A11: SOURCES (EUR m)
A12: Total new debt = PIK Notes + Bridge/Senior Facilities (disclosed structure) | B12: =B13 -> 8024.9189
A13: Total debt (EUR m) = Total Uses − Equity | B13: =B9-B18 -> 8024.9189
A14: PIK Notes (disclosed max, EUR1,530m — accrues, paid at exit; see 08 Debt Schedule) | B14: ='03 Assumptions'!B59 -> 1530
A15: Bridge/Senior Facilities (= Total debt − PIK; check against EUR6,050m ceiling in row 24) | B15: =B13-B14 -> 6494.9189
A16: (unused — real structure has two debt tranches, not three; kept as 0 so downstream refs are unaffected) | B16: 0
A17: Senior RCF EUR 1,000m — undrawn at close | B17: 0
A18: Sponsor equity — CVC/GBL/Co-Investor (disclosed commitment, fixed, not a plug) | B18: ='03 Assumptions'!B58 -> 4524.7511
A19: TOTAL SOURCES | B19: =B13+B17+B18 -> 12549.67
A21: =IF(ABS(B19-B9)<0.1,"CHECK OK: sources = uses","ERROR: S&U do not balance") -> CHECK OK: sources = uses
A22: Equity % of capitalisation | B22: =B18/B19 -> 0.36054741
A23: The fixed-rate (EUR3,350m) / floating-rate (EUR2,700m) Bridge Facility split is not separately modeled here; B15 is the blended balancing amount. USD rare-disease revenue hedge dynamics from the prior estimate no longer apply — the real facilities are EUR-denominated per the offer document.
A24: =IF(B15>'03 Assumptions'!B60,"WARNING: Bridge/Senior plug exceeds the disclosed EUR6,050m ceiling -- the refi-net-debt / fee estimates (never disclosed, always this model's own assumption) likely need tightening, not the disclosed structure","CHECK OK: within disclosed EUR6,050m bridge ceiling") -> WARNING: Bridge/Senior plug exceeds the disclosed EUR6,050m ceiling -- the refi-net-debt / fee estimates (never disclosed, always this model's own assumption) likely need tightening, not the disclosed structure
A25: Interest rate margins are NOT disclosed in the offer document ("EURIBOR plus a certain margin agreed" — undisclosed for Bridge, Senior AND PIK). Rates in the debt schedule are labeled estimates, not sourced figures.

Sheet 07 Purchase Price
A1: PURCHASE PRICE & ENTRY MULTIPLES
A3: Offer price (€/share, ex-div) | B3: ='03 Assumptions'!B20 -> 51.29
A4: Shares outstanding (m) | B4: ='03 Assumptions'!B21 -> 209.125
A5: Equity purchase price (€m) | B5: ='03 Assumptions'!B22 -> 10182.376
A6: (+) Existing net debt refinanced | B6: ='03 Assumptions'!B23 -> 1767.3
A7: Enterprise value (€m) | B7: =B5+B6 -> 11949.676
A8: EV / FY2025A EBITDA (close-date net debt, independent) | B8: =B7/'03 Assumptions'!B16 -> 12.056983
A9: EV / FY2026E EBITDA (model) | B9: =B7/'09 Operating Model'!F18 -> 11.819946
A10: Cum-dividend price (€52.00) vs undisturbed €46.06 | B10: =52/46.06-1 -> 0.12896222
A11: STRESS: EV / standardised (aggregator) EBITDA EUR 877m | B11: =B7/877 -> 13.625628
A12: Reference: Rossini/CVC VII entered 2018 at €28.00/sh = 12.9x 2017 EBITDA — identical multiple, zero expansion over 8 years.
A13: =IF(ABS(B14-12.87)<0.15,"CHECK OK: announced-basis entry ~12.9x ties to deal math","CHECK: entry multiple deviates from deal math") -> CHECK: entry multiple deviates from deal math
A14: Ref: EV/EBITDA on FY25A gross ND EUR 2,037m (announced-deal basis) | B14: =(B5+'03 Assumptions'!B49)/'03 Assumptions'!B16 -> 12.329408

Sheet 09 Operating Model
A1: OPERATING MODEL - RD / SPC SPLIT (organic; row 17-18 add BD-acquired EBITDA)
A3: €m | F3: 2026E | G3: 2027 | H3: 2028 | I3: 2029 | J3: 2030 | K3: 2031
A4: Year of hold (t) | G4: 1 | H4: 2 | I4: 3 | J4: 4 | K4: 5
A5: Rare Diseases revenue | F5: ='03 Assumptions'!B18*(1+'03 Assumptions'!B39) -> 1232.796 | G5: =F5*(1+IF(G4<=3,'03 Assumptions'!$F$6,'03 Assumptions'!$F$7)) -> 1405.3874 | H5: =G5*(1+IF(H4<=3,'03 Assumptions'!$F$6,'03 Assumptions'!$F$7)) -> 1602.1417 | I5: =H5*(1+IF(I4<=3,'03 Assumptions'!$F$6,'03 Assumptions'!$F$7)) -> 1826.4415 | J5: =I5*(1+IF(J4<=3,'03 Assumptions'!$F$6,'03 Assumptions'!$F$7)) -> 1990.8213 | K5: =J5*(1+IF(K4<=3,'03 Assumptions'!$F$6,'03 Assumptions'!$F$7)) -> 2169.9952
A6: SPC revenue | F6: ='03 Assumptions'!B19*(1+'03 Assumptions'!B40) -> 1537 | G6: =F6*(1+'03 Assumptions'!$F$8) -> 1567.74 | H6: =G6*(1+'03 Assumptions'!$F$8) -> 1599.0948 | I6: =H6*(1+'03 Assumptions'!$F$8) -> 1631.0767 | J6: =I6*(1+'03 Assumptions'!$F$8) -> 1663.6982 | K6: =J6*(1+'03 Assumptions'!$F$8) -> 1696.9722
A7: Total revenue | F7: =F5+F6 -> 2769.796 | G7: =G5+G6 -> 2973.1274 | H7: =H5+H6 -> 3201.2365 | I7: =I5+I6 -> 3457.5182 | J7: =J5+J6 -> 3654.5195 | K7: =K5+K6 -> 3866.9674
A8: EBITDA | F8: =F7*'03 Assumptions'!B41 -> 1010.9755 | G8: =G7*('03 Assumptions'!$B$41+('03 Assumptions'!$F$9-'03 Assumptions'!$B$41)*MIN(G4,3)/3) -> 1097.5795 | H8: =H7*('03 Assumptions'!$B$41+('03 Assumptions'!$F$9-'03 Assumptions'!$B$41)*MIN(H4,3)/3) -> 1195.1283 | I8: =I7*('03 Assumptions'!$B$41+('03 Assumptions'!$F$9-'03 Assumptions'!$B$41)*MIN(I4,3)/3) -> 1305.2131 | J8: =J7*('03 Assumptions'!$B$41+('03 Assumptions'!$F$9-'03 Assumptions'!$B$41)*MIN(J4,3)/3) -> 1379.5811 | K8: =K7*('03 Assumptions'!$B$41+('03 Assumptions'!$F$9-'03 Assumptions'!$B$41)*MIN(K4,3)/3) -> 1459.7802
A9: EBITDA margin | F9: =F8/F7 -> 0.365 | G9: =G8/G7 -> 0.36916667 | H9: =H8/H7 -> 0.37333333 | I9: =I8/I7 -> 0.3775 | J9: =J8/J7 -> 0.3775 | K9: =K8/K7 -> 0.3775
A10: D&A | F10: =-F7*'03 Assumptions'!$B$33 -> -218.81388 | G10: =-G7*'03 Assumptions'!$B$33 -> -234.87707 | H10: =-H7*'03 Assumptions'!$B$33 -> -252.89768 | I10: =-I7*'03 Assumptions'!$B$33 -> -273.14394 | J10: =-J7*'03 Assumptions'!$B$33 -> -288.70704 | K10: =-K7*'03 Assumptions'!$B$33 -> -305.49042
A11: EBIT | F11: =F8+F10 -> 792.16166 | G11: =G8+G10 -> 862.70248 | H11: =H8+H10 -> 942.2306 | I11: =I8+I10 -> 1032.0692 | J11: =J8+J10 -> 1090.8741 | K11: =K8+K10 -> 1154.2898
A12: Maintenance capex | F12: =-F7*'03 Assumptions'!$B$32 -> -48.47143 | G12: =-G7*'03 Assumptions'!$B$32 -> -52.02973 | H12: =-H7*'03 Assumptions'!$B$32 -> -56.021638 | I12: =-I7*'03 Assumptions'!$B$32 -> -60.506569 | J12: =-J7*'03 Assumptions'!$B$32 -> -63.954091 | K12: =-K7*'03 Assumptions'!$B$32 -> -67.671929
A13: Change in NWC (cash out) | F13: =-(F7-'03 Assumptions'!B17)*'03 Assumptions'!$B$35 -> -22.7094 | G13: =-(G7-F7)*'03 Assumptions'!$B$35 -> -30.499716 | H13: =-(H7-G7)*'03 Assumptions'!$B$35 -> -34.216356 | I13: =-(I7-H7)*'03 Assumptions'!$B$35 -> -38.44226 | J13: =-(J7-I7)*'03 Assumptions'!$B$35 -> -29.550191 | K13: =-(K7-J7)*'03 Assumptions'!$B$35 -> -31.867182
A15: RD % of revenue | F15: =F5/F7 -> 0.44508549 | G15: =G5/G7 -> 0.47269667 | H15: =H5/H7 -> 0.50047589 | I15: =I5/I7 -> 0.52825218 | J15: =J5/J7 -> 0.54475596 | K15: =K5/K7 -> 0.56116201
A16: EBITDA growth | G16: =G8/F8-1 -> 0.0856638 | H16: =H8/G8-1 -> 0.088876237 | I16: =I8/H8-1 -> 0.092111316 | J16: =J8/I8-1 -> 0.056977652 | K16: =K8/J8-1 -> 0.058132917
A17: Acquired EBITDA from BD (cumulative; spend/9.0x, contributes from year after spend) | F17: 0 | G17: 0 | H17: =G17+'03 Assumptions'!$F$13/'03 Assumptions'!$B$43 -> 44.444444 | I17: =H17+'03 Assumptions'!$F$13/'03 Assumptions'!$B$43 -> 88.888889 | J17: =I17+'03 Assumptions'!$F$13/'03 Assumptions'!$B$43 -> 133.33333 | K17: =J17+'03 Assumptions'!$F$13/'03 Assumptions'!$B$43 -> 177.77778
A18: TOTAL EBITDA (organic + acquired) | F18: =F8+F17 -> 1010.9755 | G18: =G8+G17 -> 1097.5795 | H18: =H8+H17 -> 1239.5727 | I18: =I8+I17 -> 1394.102 | J18: =J8+J17 -> 1512.9144 | K18: =K8+K17 -> 1637.558
A20: =IF(AND(F8>995,F8<1031),"CHECK OK: 2026E EBITDA within guidance 995-1,030","CHECK: 2026E EBITDA outside guidance") -> CHECK OK: 2026E EBITDA within guidance 995-1,030

Sheet 08 Debt Schedule
A1: DEBT SCHEDULE — v4: PIK Notes (accrue, non-cash) + Bridge/Senior Facilities (100% cash sweep)
A3: €m | G3: 2027 | H3: 2028 | I3: 2029 | J3: 2030 | K3: 2031
A5: PIK Notes beginning | G5: ='06 Sources & Uses'!B14 -> 1530 | H5: =G8 -> 1661.58 | I5: =H8 -> 1804.4759 | J5: =I8 -> 1959.6608 | K5: =J8 -> 2128.1916
A6: PIK accrued interest (paid-in-kind, added to principal, non-cash) | G6: =G5*'03 Assumptions'!$B$63 -> 131.58 | H6: =H5*'03 Assumptions'!$B$63 -> 142.89588 | I6: =I5*'03 Assumptions'!$B$63 -> 155.18493 | J6: =J5*'03 Assumptions'!$B$63 -> 168.53083 | K6: =K5*'03 Assumptions'!$B$63 -> 183.02448
A7: cash sweep (PIK is not prepayable via sweep — junior/accretes to maturity) | G7: 0 | H7: 0 | I7: 0 | J7: 0 | K7: 0
A8: PIK Notes ending | G8: =G5+G6+G7 -> 1661.58 | H8: =H5+H6+H7 -> 1804.4759 | I8: =I5+I6+I7 -> 1959.6608 | J8: =J5+J6+J7 -> 2128.1916 | K8: =K5+K6+K7 -> 2311.2161
A10: Bridge/Senior Facilities beginning | G10: ='06 Sources & Uses'!B15 -> 6494.9189 | H10: =G13 -> 6391.8444 | I10: =H13 -> 6167.9854 | J10: =I13 -> 5819.1308 | K10: =J13 -> 5355.2889
A11: mandatory amort (not disclosed in offer doc -- assumed 0; deleveraging is via cash sweep only) | G11: 0 | H11: 0 | I11: 0 | J11: 0 | K11: 0
A12: cash sweep | G12: =-MIN(G10+G11,G34) -> -103.07448 | H12: =-MIN(H10+H11,H34) -> -223.85906 | I12: =-MIN(I10+I11,I34) -> -348.85462 | J12: =-MIN(J10+J11,J34) -> -463.84183 | K12: =-MIN(K10+K11,K34) -> -977.18649
A13: Bridge/Senior Facilities ending | G13: =G10+G11+G12 -> 6391.8444 | H13: =H10+H11+H12 -> 6167.9854 | I13: =I10+I11+I12 -> 5819.1308 | J13: =J10+J11+J12 -> 5355.2889 | K13: =K10+K11+K12 -> 4378.1025
A15: (unused — real structure has two debt tranches, not three) | G15: ='06 Sources & Uses'!B16 -> 0 | H15: ='06 Sources & Uses'!B16 -> 0 | I15: ='06 Sources & Uses'!B16 -> 0 | J15: ='06 Sources & Uses'!B16 -> 0 | K15: ='06 Sources & Uses'!B16 -> 0
A17: Total debt ending | G17: =G8+G13+G15 -> 8053.4244 | H17: =H8+H13+H15 -> 7972.4613 | I17: =I8+I13+I15 -> 7778.7916 | J17: =J8+J13+J15 -> 7483.4806 | K17: =K8+K13+K15 -> 6689.3186
A18: Excess cash (accumulates once TLBs repaid) | G18: =MAX(0,G34+G7+G12) -> 0 | H18: =MAX(0,H34+H7+H12)+G18 -> 0 | I18: =MAX(0,I34+I7+I12)+H18 -> 0 | J18: =MAX(0,J34+J7+J12)+I18 -> 0 | K18: =MAX(0,K34+K7+K12)+J18 -> 0
A19: NET DEBT ending | G19: =G17-G18-'03 Assumptions'!$B$44 -> 7803.4244 | H19: =H17-H18-'03 Assumptions'!$B$44 -> 7722.4613 | I19: =I17-I18-'03 Assumptions'!$B$44 -> 7528.7916 | J19: =J17-J18-'03 Assumptions'!$B$44 -> 7233.4806 | K19: =K17-K18-'03 Assumptions'!$B$44 -> 6439.3186
A21: Interest: PIK Notes (non-cash accrual — see row 6; excluded from cash interest) | G21: 0 | H21: 0 | I21: 0 | J21: 0 | K21: 0
A22: Interest: Bridge/Senior Facilities (cash-pay, EURIBOR + estimated margin — NOT DISCLOSED, see 03 Assumptions B62) | G22: =-G10*'03 Assumptions'!$B$62 -> -379.95276 | H22: =-H10*'03 Assumptions'!$B$62 -> -373.9229 | I22: =-I10*'03 Assumptions'!$B$62 -> -360.82715 | J22: =-J10*'03 Assumptions'!$B$62 -> -340.41915 | K22: =-K10*'03 Assumptions'!$B$62 -> -313.2844
A23: (unused — real structure has two debt tranches, not three) | G23: 0 | H23: 0 | I23: 0 | J23: 0 | K23: 0
A24: RCF commitment fee | G24: =-'03 Assumptions'!$B$61*'03 Assumptions'!$B$31 -> -4 | H24: =-'03 Assumptions'!$B$61*'03 Assumptions'!$B$31 -> -4 | I24: =-'03 Assumptions'!$B$61*'03 Assumptions'!$B$31 -> -4 | J24: =-'03 Assumptions'!$B$61*'03 Assumptions'!$B$31 -> -4 | K24: =-'03 Assumptions'!$B$61*'03 Assumptions'!$B$31 -> -4
A25: Total cash interest | G25: =SUM(G21:G24) -> -383.95276 | H25: =SUM(H21:H24) -> -377.9229 | I25: =SUM(I21:I24) -> -364.82715 | J25: =SUM(J21:J24) -> -344.41915 | K25: =SUM(K21:K24) -> -317.2844
A26: (-) BD / in-licensing spend (funded pre-sweep) | G26: =-'03 Assumptions'!$F$13 -> -400 | H26: =-'03 Assumptions'!$F$13 -> -400 | I26: =-'03 Assumptions'!$F$13 -> -400 | J26: =-'03 Assumptions'!$F$13 -> -400 | K26: 0
A27: EBITDA | G27: ='09 Operating Model'!G18 -> 1097.5795 | H27: ='09 Operating Model'!H18 -> 1239.5727 | I27: ='09 Operating Model'!I18 -> 1394.102 | J27: ='09 Operating Model'!J18 -> 1512.9144 | K27: ='09 Operating Model'!K18 -> 1637.558
A28: (-) Maintenance capex | G28: ='09 Operating Model'!G12 -> -52.02973 | H28: ='09 Operating Model'!H12 -> -56.021638 | I28: ='09 Operating Model'!I12 -> -60.506569 | J28: ='09 Operating Model'!J12 -> -63.954091 | K28: ='09 Operating Model'!K12 -> -67.671929
A29: (-) Change in NWC | G29: ='09 Operating Model'!G13 -> -30.499716 | H29: ='09 Operating Model'!H13 -> -34.216356 | I29: ='09 Operating Model'!I13 -> -38.44226 | J29: ='09 Operating Model'!J13 -> -29.550191 | K29: ='09 Operating Model'!K13 -> -31.867182
A30: (-) Cash taxes (24% of max(0, EBITDA - D&A - interest)) | G30: =-'03 Assumptions'!$B$34*MAX(0,G27+'09 Operating Model'!G10-MIN(-G25,'03 Assumptions'!$B$45*G27)) -> -128.02287 | H30: =-'03 Assumptions'!$B$34*MAX(0,H27+'09 Operating Model'!H10-MIN(-H25,'03 Assumptions'!$B$45*H27)) -> -147.55278 | I30: =-'03 Assumptions'!$B$34*MAX(0,I27+'09 Operating Model'!I10-MIN(-I25,'03 Assumptions'!$B$45*I27)) -> -181.47142 | J30: =-'03 Assumptions'!$B$34*MAX(0,J27+'09 Operating Model'!J10-MIN(-J25,'03 Assumptions'!$B$45*J27)) -> -211.14918 | K30: =-'03 Assumptions'!$B$34*MAX(0,K27+'09 Operating Model'!K10-MIN(-K25,'03 Assumptions'!$B$45*K27)) -> -243.54795
A31: (-) Cash interest & fees | G31: =G25 -> -383.95276 | H31: =H25 -> -377.9229 | I31: =I25 -> -364.82715 | J31: =J25 -> -344.41915 | K31: =K25 -> -317.2844
A32: FCF before debt service | G32: =G27+G28+G29+G30+G31+G26 -> 103.07448 | H32: =H27+H28+H29+H30+H31+H26 -> 223.85906 | I32: =I27+I28+I29+I30+I31+I26 -> 348.85462 | J32: =J27+J28+J29+J30+J31+J26 -> 463.84183 | K32: =K27+K28+K29+K30+K31+K26 -> 977.18649
A33: (-) Mandatory amortisation (Bridge/Senior only — PIK accrual is non-cash, excluded) | G33: =G11 -> 0 | H33: =H11 -> 0 | I33: =I11 -> 0 | J33: =J11 -> 0 | K33: =K11 -> 0
A34: FCF available for sweep | G34: =MAX(0,G32+G33)*'03 Assumptions'!$F$12 -> 103.07448 | H34: =MAX(0,H32+H33)*'03 Assumptions'!$F$12 -> 223.85906 | I34: =MAX(0,I32+I33)*'03 Assumptions'!$F$12 -> 348.85462 | J34: =MAX(0,J32+J33)*'03 Assumptions'!$F$12 -> 463.84183 | K34: =MAX(0,K32+K33)*'03 Assumptions'!$F$12 -> 977.18649
A36: Leverage: net debt / EBITDA | G36: =G19/G27 -> 7.1096664 | H36: =H19/H27 -> 6.229938 | I36: =I19/I27 -> 5.4004596 | J36: =J19/J27 -> 4.7811564 | K36: =K19/K27 -> 3.9322691
A37: Interest coverage: EBITDA / cash interest | G37: =-G27/G25 -> 2.8586318 | H37: =-H27/H25 -> 3.2799619 | I37: =-I27/I25 -> 3.8212672 | J37: =-J27/J25 -> 4.3926548 | K37: =-K27/K25 -> 5.1611675
A38: DSCR: (EBITDA-capex-tax)/(interest+amort) | G38: =(G27+G28+G30)/-(G25-G33+0.0001) -> 2.3896877 | H38: =(H27+H28+H30)/-(H25-H33+0.0001) -> 2.7412962 | I38: =(I27+I28+I30)/-(I25-I33+0.0001) -> 3.1580006 | J38: =(J27+J28+J30)/-(J25-J33+0.0001) -> 3.5939103 | K38: =(K27+K28+K30)/-(K25-K33+0.0001) -> 4.1802827
A39: Total interest coverage (incl. PIK accrual, non-cash): EBITDA / (cash interest + PIK accrual) | G39: =-G27/(G25-G6) -> 2.12902 | H39: =-H27/(H25-H6) -> 2.3800461 | I39: =-I27/(I25-I6) -> 2.6809032 | J39: =-J27/(J25-J6) -> 2.9494385 | K39: =-K27/(K25-K6) -> 3.2730939
A40: =IF(G37>2.5,"CHECK OK: year-1 interest coverage > 2.5x","CHECK: coverage tight — review leverage") -> CHECK OK: year-1 interest coverage > 2.5x
A42: Sweep order: Bridge/Senior Facilities, 100% cash sweep. PIK Notes accrue non-cash (paid in kind) and are not swept -- outstanding balance grows and is repaid at exit/maturity, per the offer document (8yr maturity, EURIBOR+margin, margin undisclosed).
A43: v2: BD spend deducted pre-sweep; taxes apply ATAD 30%-of-EBITDA interest deductibility cap (carryforward ignored - conservative).
A44: v4 (03-Sep-2026): structure rebuilt from the CONSOB offer document (31 Aug 2026) -- see 03 Assumptions rows 56-64 and 06 Sources & Uses. Bridge/Senior and PIK rates are labeled estimates; the offer document does not disclose margins.

Sheet 10 Returns
A1: RETURNS — IRR / MOIC + BRIDGES
A3: Entry equity (from S&U) | B3: ='06 Sources & Uses'!B18 -> 4524.7511
A4: Exit year EBITDA (2031, incl. BD) | B4: ='09 Operating Model'!K18 -> 1637.558
A5: Exit multiple (scenario) | B5: ='03 Assumptions'!F11 -> 11.5
A6: Exit enterprise value | B6: =B4*B5 -> 18831.916
A7: (-) Net debt at exit | B7: ='08 Debt Schedule'!K19 -> 6439.3186
A8: Exit equity value | B8: =B6-B7 -> 12392.598
A9: MOIC | B9: =B8/B3 -> 2.7388463
A10: Hold (years) | B10: ='03 Assumptions'!B42 -> 5
A11: IRR (single exit flow) | B11: =B9^(1/B10)-1 -> 0.22324524
A14: MOIC BRIDGE (multiples of entry equity)
A15: Entry equity (1.00x) | B15: 1
A16: (+) EBITDA growth at entry multiple | B16: =(B4-'03 Assumptions'!B16)*'07 Purchase Price'!B8/B3 -> 1.7225992
A17: (+) Multiple expansion/(compression) | B17: =(B5-'07 Purchase Price'!B8)*B4/B3 -> -0.20157845
A18: (+) Deleveraging (net debt entry - exit) | B18: =('06 Sources & Uses'!B13-'03 Assumptions'!B44-'08 Debt Schedule'!K19)/B3 -> 0.29517654
A19: (-) Fees & frictions (residual) | B19: =B9-B15-B16-B17-B18 -> -0.077350979
A20: MOIC (check) | B20: =SUM(B15:B19) -> 2.7388463
A21: =IF(ABS(B20-B9)<0.01,"CHECK OK: bridge ties to MOIC","ERROR: bridge broken") -> CHECK OK: bridge ties to MOIC
A23: IRR / MOIC BY EXIT YEAR (live)
A24: Exit year | B24: 2029 | C24: 2030 | D24: 2031
A25: Exit equity (mult x EBITDA - net debt) | B25: ='03 Assumptions'!F11*'09 Operating Model'!I18-'08 Debt Schedule'!I19 -> 8503.3816 | C25: ='03 Assumptions'!F11*'09 Operating Model'!J18-'08 Debt Schedule'!J19 -> 10165.035 | D25: ='03 Assumptions'!F11*'09 Operating Model'!K18-'08 Debt Schedule'!K19 -> 12392.598
A26: MOIC | B26: =B25/'06 Sources & Uses'!B18 -> 1.8793037 | C26: =C25/'06 Sources & Uses'!B18 -> 2.2465403 | D26: =D25/'06 Sources & Uses'!B18 -> 2.7388463
A27: IRR | B27: =(B25/'06 Sources & Uses'!B18)^(1/3)-1 -> 0.23404878 | C27: =(C25/'06 Sources & Uses'!B18)^(1/4)-1 -> 0.22427379 | D27: =(D25/'06 Sources & Uses'!B18)^(1/5)-1 -> 0.22324524
A29: No interim dividends/recaps modeled (conservative). Dividend recap optionality would raise IRR, not MOIC.
A31: RECAP OPTIONALITY: Sponsor-consistent case includes a dividend recap to ~4.0x leverage when headroom allows (~Yr4/5), adding ~1.0pt IRR.
A32: Modeled here as conservative 100% sweep to ~1.0x exit leverage. Extending the hold to 7 years requires modeling this recap AND interest income on excess cash first.

Sheet 11 Sensitivities
A1: SENSITIVITIES - EXACT full-recursion engines (no approximations)
A2: All grids run a complete 3-tranche debt recursion (interest, ATAD tax cap, BD spend, mandatory amort, sequential sweep,
A3: excess cash) per case. Engine A scales operating items with EBITDA (axis definition); Engine B uses the live EBITDA path.
A5: GRID 1 - Exit multiple (rows) x exit year (cols) - IRR, fully live
C6: 2029 | D6: 2030 | E6: 2031
B7: 9 | C7: =(($B7*'09 Operating Model'!$I$18-'08 Debt Schedule'!$I$19)/'06 Sources & Uses'!$B$18)^(1/3)-1 -> 0.035099994 | D7: =(($B7*'09 Operating Model'!$J$18-'08 Debt Schedule'!$J$19)/'06 Sources & Uses'!$B$18)^(1/4)-1 -> 0.089816239 | E7: =(($B7*'09 Operating Model'!$K$18-'08 Debt Schedule'!$K$19)/'06 Sources & Uses'!$B$18)^(1/5)-1 -> 0.12897183
B8: 10 | C8: =(($B8*'09 Operating Model'!$I$18-'08 Debt Schedule'!$I$19)/'06 Sources & Uses'!$B$18)^(1/3)-1 -> 0.12323709 | D8: =(($B8*'09 Operating Model'!$J$18-'08 Debt Schedule'!$J$19)/'06 Sources & Uses'!$B$18)^(1/4)-1 -> 0.14933991 | E8: =(($B8*'09 Operating Model'!$K$18-'08 Debt Schedule'!$K$19)/'06 Sources & Uses'!$B$18)^(1/5)-1 -> 0.17037668
B9: 11 | C9: =(($B9*'09 Operating Model'!$I$18-'08 Debt Schedule'!$I$19)/'06 Sources & Uses'!$B$18)^(1/3)-1 -> 0.19936328 | D9: =(($B9*'09 Operating Model'!$J$18-'08 Debt Schedule'!$J$19)/'06 Sources & Uses'!$B$18)^(1/4)-1 -> 0.20083221 | E9: =(($B9*'09 Operating Model'!$K$18-'08 Debt Schedule'!$K$19)/'06 Sources & Uses'!$B$18)^(1/5)-1 -> 0.20663633
B10: 11.5 | C10: =(($B10*'09 Operating Model'!$I$18-'08 Debt Schedule'!$I$19)/'06 Sources & Uses'!$B$18)^(1/3)-1 -> 0.23404878 | D10: =(($B10*'09 Operating Model'!$J$18-'08 Debt Schedule'!$J$19)/'06 Sources & Uses'!$B$18)^(1/4)-1 -> 0.22427379 | E10: =(($B10*'09 Operating Model'!$K$18-'08 Debt Schedule'!$K$19)/'06 Sources & Uses'!$B$18)^(1/5)-1 -> 0.22324524
B11: 12 | C11: =(($B11*'09 Operating Model'!$I$18-'08 Debt Schedule'!$I$19)/'06 Sources & Uses'!$B$18)^(1/3)-1 -> 0.26688692 | D11: =(($B11*'09 Operating Model'!$J$18-'08 Debt Schedule'!$J$19)/'06 Sources & Uses'!$B$18)^(1/4)-1 -> 0.24644129 | E11: =(($B11*'09 Operating Model'!$K$18-'08 Debt Schedule'!$K$19)/'06 Sources & Uses'!$B$18)^(1/5)-1 -> 0.23899821
B12: 12.9 | C12: =(($B12*'09 Operating Model'!$I$18-'08 Debt Schedule'!$I$19)/'06 Sources & Uses'!$B$18)^(1/3)-1 -> 0.32204074 | D12: =(($B12*'09 Operating Model'!$J$18-'08 Debt Schedule'!$J$19)/'06 Sources & Uses'!$B$18)^(1/4)-1 -> 0.28359632 | E12: =(($B12*'09 Operating Model'!$K$18-'08 Debt Schedule'!$K$19)/'06 Sources & Uses'!$B$18)^(1/5)-1 -> 0.26548474
B13: 14 | C13: =(($B13*'09 Operating Model'!$I$18-'08 Debt Schedule'!$I$19)/'06 Sources & Uses'!$B$18)^(1/3)-1 -> 0.38375234 | D13: =(($B13*'09 Operating Model'!$J$18-'08 Debt Schedule'!$J$19)/'06 Sources & Uses'!$B$18)^(1/4)-1 -> 0.32502487 | E13: =(($B13*'09 Operating Model'!$K$18-'08 Debt Schedule'!$K$19)/'06 Sources & Uses'!$B$18)^(1/5)-1 -> 0.29511018
A16: ENGINE A - total-EBITDA CAGR cases (cols C-G). Full recursion below; results in GRID 2.
A17: EBITDA CAGR 2026-31 | C17: 0.02 | D17: 0.04 | E17: 0.06 | F17: 0.08 | G17: 0.1
A21: EBITDA year 2027 | C21: ='09 Operating Model'!$F$18*(1+C$17)^1 -> 1031.1951 | D21: ='09 Operating Model'!$F$18*(1+D$17)^1 -> 1051.4146 | E21: ='09 Operating Model'!$F$18*(1+E$17)^1 -> 1071.6341 | F21: ='09 Operating Model'!$F$18*(1+F$17)^1 -> 1091.8536 | G21: ='09 Operating Model'!$F$18*(1+G$17)^1 -> 1112.0731
A22: EBITDA year 2028 | C22: ='09 Operating Model'!$F$18*(1+C$17)^2 -> 1051.819 | D22: ='09 Operating Model'!$F$18*(1+D$17)^2 -> 1093.4711 | E22: ='09 Operating Model'!$F$18*(1+E$17)^2 -> 1135.9321 | F22: ='09 Operating Model'!$F$18*(1+F$17)^2 -> 1179.2019 | G22: ='09 Operating Model'!$F$18*(1+G$17)^2 -> 1223.2804
A23: EBITDA year 2029 | C23: ='09 Operating Model'!$F$18*(1+C$17)^3 -> 1072.8553 | D23: ='09 Operating Model'!$F$18*(1+D$17)^3 -> 1137.21 | E23: ='09 Operating Model'!$F$18*(1+E$17)^3 -> 1204.088 | F23: ='09 Operating Model'!$F$18*(1+F$17)^3 -> 1273.538 | G23: ='09 Operating Model'!$F$18*(1+G$17)^3 -> 1345.6084
A24: EBITDA year 2030 | C24: ='09 Operating Model'!$F$18*(1+C$17)^4 -> 1094.3124 | D24: ='09 Operating Model'!$F$18*(1+D$17)^4 -> 1182.6984 | E24: ='09 Operating Model'!$F$18*(1+E$17)^4 -> 1276.3333 | F24: ='09 Operating Model'!$F$18*(1+F$17)^4 -> 1375.4211 | G24: ='09 Operating Model'!$F$18*(1+G$17)^4 -> 1480.1693
A25: EBITDA year 2031 | C25: ='09 Operating Model'!$F$18*(1+C$17)^5 -> 1116.1987 | D25: ='09 Operating Model'!$F$18*(1+D$17)^5 -> 1230.0063 | E25: ='09 Operating Model'!$F$18*(1+E$17)^5 -> 1352.9133 | F25: ='09 Operating Model'!$F$18*(1+F$17)^5 -> 1485.4547 | G25: ='09 Operating Model'!$F$18*(1+G$17)^5 -> 1628.1862
A28: FCF pre-amort 2027 | C28: =C21+(('08 Debt Schedule'!G28+'08 Debt Schedule'!G29)*C21/'09 Operating Model'!G18)+(-'03 Assumptions'!$B$34*MAX(0,C21+('09 Operating Model'!G10*C21/'09 Operating Model'!G18)-MIN((('03 Assumptions'!$B$26+'03 Assumptions'!$B$27)*'06 Sources & Uses'!$B$14+'03 Assumptions'!$B$28*'06 Sources & Uses'!$B$15+'03 Assumptions'!$B$29*'06 Sources & Uses'!$B$16+'03 Assumptions'!$B$30*'03 Assumptions'!$B$31),'03 Assumptions'!$B$45*C21)))-(('03 Assumptions'!$B$26+'03 Assumptions'!$B$27)*'06 Sources & Uses'!$B$14+'03 Assumptions'!$B$28*'06 Sources & Uses'!$B$15+'03 Assumptions'!$B$29*'06 Sources & Uses'!$B$16+'03 Assumptions'!$B$30*'03 Assumptions'!$B$31)-'03 Assumptions'!$F$13 -> -129.00913 | D28: =D21+(('08 Debt Schedule'!G28+'08 Debt Schedule'!G29)*D21/'09 Operating Model'!G18)+(-'03 Assumptions'!$B$34*MAX(0,D21+('09 Operating Model'!G10*D21/'09 Operating Model'!G18)-MIN((('03 Assumptions'!$B$26+'03 Assumptions'!$B$27)*'06 Sources & Uses'!$B$14+'03 Assumptions'!$B$28*'06 Sources & Uses'!$B$15+'03 Assumptions'!$B$29*'06 Sources & Uses'!$B$16+'03 Assumptions'!$B$30*'03 Assumptions'!$B$31),'03 Assumptions'!$B$45*D21)))-(('03 Assumptions'!$B$26+'03 Assumptions'!$B$27)*'06 Sources & Uses'!$B$14+'03 Assumptions'!$B$28*'06 Sources & Uses'!$B$15+'03 Assumptions'!$B$29*'06 Sources & Uses'!$B$16+'03 Assumptions'!$B$30*'03 Assumptions'!$B$31)-'03 Assumptions'!$F$13 -> -112.66839 | E28: =E21+(('08 Debt Schedule'!G28+'08 Debt Schedule'!G29)*E21/'09 Operating Model'!G18)+(-'03 Assumptions'!$B$34*MAX(0,E21+('09 Operating Model'!G10*E21/'09 Operating Model'!G18)-MIN((('03 Assumptions'!$B$26+'03 Assumptions'!$B$27)*'06 Sources & Uses'!$B$14+'03 Assumptions'!$B$28*'06 Sources & Uses'!$B$15+'03 Assumptions'!$B$29*'06 Sources & Uses'!$B$16+'03 Assumptions'!$B$30*'03 Assumptions'!$B$31),'03 Assumptions'!$B$45*E21)))-(('03 Assumptions'!$B$26+'03 Assumptions'!$B$27)*'06 Sources & Uses'!$B$14+'03 Assumptions'!$B$28*'06 Sources & Uses'!$B$15+'03 Assumptions'!$B$29*'06 Sources & Uses'!$B$16+'03 Assumptions'!$B$30*'03 Assumptions'!$B$31)-'03 Assumptions'!$F$13 -> -96.327657 | F28: =F21+(('08 Debt Schedule'!G28+'08 Debt Schedule'!G29)*F21/'09 Operating Model'!G18)+(-'03 Assumptions'!$B$34*MAX(0,F21+('09 Operating Model'!G10*F21/'09 Operating Model'!G18)-MIN((('03 Assumptions'!$B$26+'03 Assumptions'!$B$27)*'06 Sources & Uses'!$B$14+'03 Assumptions'!$B$28*'06 Sources & Uses'!$B$15+'03 Assumptions'!$B$29*'06 Sources & Uses'!$B$16+'03 Assumptions'!$B$30*'03 Assumptions'!$B$31),'03 Assumptions'!$B$45*F21)))-(('03 Assumptions'!$B$26+'03 Assumptions'!$B$27)*'06 Sources & Uses'!$B$14+'03 Assumptions'!$B$28*'06 Sources & Uses'!$B$15+'03 Assumptions'!$B$29*'06 Sources & Uses'!$B$16+'03 Assumptions'!$B$30*'03 Assumptions'!$B$31)-'03 Assumptions'!$F$13 -> -79.986922 | G28: =G21+(('08 Debt Schedule'!G28+'08 Debt Schedule'!G29)*G21/'09 Operating Model'!G18)+(-'03 Assumptions'!$B$34*MAX(0,G21+('09 Operating Model'!G10*G21/'09 Operating Model'!G18)-MIN((('03 Assumptions'!$B$26+'03 Assumptions'!$B$27)*'06 Sources & Uses'!$B$14+'03 Assumptions'!$B$28*'06 Sources & Uses'!$B$15+'03 Assumptions'!$B$29*'06 Sources & Uses'!$B$16+'03 Assumptions'!$B$30*'03 Assumptions'!$B$31),'03 Assumptions'!$B$45*G21)))-(('03 Assumptions'!$B$26+'03 Assumptions'!$B$27)*'06 Sources & Uses'!$B$14+'03 Assumptions'!$B$28*'06 Sources & Uses'!$B$15+'03 Assumptions'!$B$29*'06 Sources & Uses'!$B$16+'03 Assumptions'!$B$30*'03 Assumptions'!$B$31)-'03 Assumptions'!$F$13 -> -63.646187
A29: FCF pre-amort 2028 | C29: =C22+(('08 Debt Schedule'!H28+'08 Debt Schedule'!H29)*C22/'09 Operating Model'!H18)+(-'03 Assumptions'!$B$34*MAX(0,C22+('09 Operating Model'!H10*C22/'09 Operating Model'!H18)-MIN((('03 Assumptions'!$B$26+'03 Assumptions'!$B$27)*C35+'03 Assumptions'!$B$28*C42+'03 Assumptions'!$B$29*'06 Sources & Uses'!$B$16+'03 Assumptions'!$B$30*'03 Assumptions'!$B$31),'03 Assumptions'!$B$45*C22)))-(('03 Assumptions'!$B$26+'03 Assumptions'!$B$27)*C35+'03 Assumptions'!$B$28*C42+'03 Assumptions'!$B$29*'06 Sources & Uses'!$B$16+'03 Assumptions'!$B$30*'03 Assumptions'!$B$31)-'03 Assumptions'!$F$13 -> -106.73723 | D29: =D22+(('08 Debt Schedule'!H28+'08 Debt Schedule'!H29)*D22/'09 Operating Model'!H18)+(-'03 Assumptions'!$B$34*MAX(0,D22+('09 Operating Model'!H10*D22/'09 Operating Model'!H18)-MIN((('03 Assumptions'!$B$26+'03 Assumptions'!$B$27)*D35+'03 Assumptions'!$B$28*D42+'03 Assumptions'!$B$29*'06 Sources & Uses'!$B$16+'03 Assumptions'!$B$30*'03 Assumptions'!$B$31),'03 Assumptions'!$B$45*D22)))-(('03 Assumptions'!$B$26+'03 Assumptions'!$B$27)*D35+'03 Assumptions'!$B$28*D42+'03 Assumptions'!$B$29*'06 Sources & Uses'!$B$16+'03 Assumptions'!$B$30*'03 Assumptions'!$B$31)-'03 Assumptions'!$F$13 -> -73.075298 | E29: =E22+(('08 Debt Schedule'!H28+'08 Debt Schedule'!H29)*E22/'09 Operating Model'!H18)+(-'03 Assumptions'!$B$34*MAX(0,E22+('09 Operating Model'!H10*E22/'09 Operating Model'!H18)-MIN((('03 Assumptions'!$B$26+'03 Assumptions'!$B$27)*E35+'03 Assumptions'!$B$28*E42+'03 Assumptions'!$B$29*'06 Sources & Uses'!$B$16+'03 Assumptions'!$B$30*'03 Assumptions'!$B$31),'03 Assumptions'!$B$45*E22)))-(('03 Assumptions'!$B$26+'03 Assumptions'!$B$27)*E35+'03 Assumptions'!$B$28*E42+'03 Assumptions'!$B$29*'06 Sources & Uses'!$B$16+'03 Assumptions'!$B$30*'03 Assumptions'!$B$31)-'03 Assumptions'!$F$13 -> -38.759734 | F29: =F22+(('08 Debt Schedule'!H28+'08 Debt Schedule'!H29)*F22/'09 Operating Model'!H18)+(-'03 Assumptions'!$B$34*MAX(0,F22+('09 Operating Model'!H10*F22/'09 Operating Model'!H18)-MIN((('03 Assumptions'!$B$26+'03 Assumptions'!$B$27)*F35+'03 Assumptions'!$B$28*F42+'03 Assumptions'!$B$29*'06 Sources & Uses'!$B$16+'03 Assumptions'!$B$30*'03 Assumptions'!$B$31),'03 Assumptions'!$B$45*F22)))-(('03 Assumptions'!$B$26+'03 Assumptions'!$B$27)*F35+'03 Assumptions'!$B$28*F42+'03 Assumptions'!$B$29*'06 Sources & Uses'!$B$16+'03 Assumptions'!$B$30*'03 Assumptions'!$B$31)-'03 Assumptions'!$F$13 -> -3.7905414 | G29: =G22+(('08 Debt Schedule'!H28+'08 Debt Schedule'!H29)*G22/'09 Operating Model'!H18)+(-'03 Assumptions'!$B$34*MAX(0,G22+('09 Operating Model'!H10*G22/'09 Operating Model'!H18)-MIN((('03 Assumptions'!$B$26+'03 Assumptions'!$B$27)*G35+'03 Assumptions'!$B$28*G42+'03 Assumptions'!$B$29*'06 Sources & Uses'!$B$16+'03 Assumptions'!$B$30*'03 Assumptions'!$B$31),'03 Assumptions'!$B$45*G22)))-(('03 Assumptions'!$B$26+'03 Assumptions'!$B$27)*G35+'03 Assumptions'!$B$28*G42+'03 Assumptions'!$B$29*'06 Sources & Uses'!$B$16+'03 Assumptions'!$B$30*'03 Assumptions'!$B$31)-'03 Assumptions'!$F$13 -> 31.832281
A30: FCF pre-amort 2029 | C30: =C23+(('08 Debt Schedule'!I28+'08 Debt Schedule'!I29)*C23/'09 Operating Model'!I18)+(-'03 Assumptions'!$B$34*MAX(0,C23+('09 Operating Model'!I10*C23/'09 Operating Model'!I18)-MIN((('03 Assumptions'!$B$26+'03 Assumptions'!$B$27)*C36+'03 Assumptions'!$B$28*C43+'03 Assumptions'!$B$29*'06 Sources & Uses'!$B$16+'03 Assumptions'!$B$30*'03 Assumptions'!$B$31),'03 Assumptions'!$B$45*C23)))-(('03 Assumptions'!$B$26+'03 Assumptions'!$B$27)*C36+'03 Assumptions'!$B$28*C43+'03 Assumptions'!$B$29*'06 Sources & Uses'!$B$16+'03 Assumptions'!$B$30*'03 Assumptions'!$B$31)-'03 Assumptions'!$F$13 -> -84.262403 | D30: =D23+(('08 Debt Schedule'!I28+'08 Debt Schedule'!I29)*D23/'09 Operating Model'!I18)+(-'03 Assumptions'!$B$34*MAX(0,D23+('09 Operating Model'!I10*D23/'09 Operating Model'!I18)-MIN((('03 Assumptions'!$B$26+'03 Assumptions'!$B$27)*D36+'03 Assumptions'!$B$28*D43+'03 Assumptions'!$B$29*'06 Sources & Uses'!$B$16+'03 Assumptions'!$B$30*'03 Assumptions'!$B$31),'03 Assumptions'!$B$45*D23)))-(('03 Assumptions'!$B$26+'03 Assumptions'!$B$27)*D36+'03 Assumptions'!$B$28*D43+'03 Assumptions'!$B$29*'06 Sources & Uses'!$B$16+'03 Assumptions'!$B$30*'03 Assumptions'!$B$31)-'03 Assumptions'!$F$13 -> -32.260876 | E30: =E23+(('08 Debt Schedule'!I28+'08 Debt Schedule'!I29)*E23/'09 Operating Model'!I18)+(-'03 Assumptions'!$B$34*MAX(0,E23+('09 Operating Model'!I10*E23/'09 Operating Model'!I18)-MIN((('03 Assumptions'!$B$26+'03 Assumptions'!$B$27)*E36+'03 Assumptions'!$B$28*E43+'03 Assumptions'!$B$29*'06 Sources & Uses'!$B$16+'03 Assumptions'!$B$30*'03 Assumptions'!$B$31),'03 Assumptions'!$B$45*E23)))-(('03 Assumptions'!$B$26+'03 Assumptions'!$B$27)*E36+'03 Assumptions'!$B$28*E43+'03 Assumptions'!$B$29*'06 Sources & Uses'!$B$16+'03 Assumptions'!$B$30*'03 Assumptions'!$B$31)-'03 Assumptions'!$F$13 -> 21.779669 | F30: =F23+(('08 Debt Schedule'!I28+'08 Debt Schedule'!I29)*F23/'09 Operating Model'!I18)+(-'03 Assumptions'!$B$34*MAX(0,F23+('09 Operating Model'!I10*F23/'09 Operating Model'!I18)-MIN((('03 Assumptions'!$B$26+'03 Assumptions'!$B$27)*F36+'03 Assumptions'!$B$28*F43+'03 Assumptions'!$B$29*'06 Sources & Uses'!$B$16+'03 Assumptions'!$B$30*'03 Assumptions'!$B$31),'03 Assumptions'!$B$45*F23)))-(('03 Assumptions'!$B$26+'03 Assumptions'!$B$27)*F36+'03 Assumptions'!$B$28*F43+'03 Assumptions'!$B$29*'06 Sources & Uses'!$B$16+'03 Assumptions'!$B$30*'03 Assumptions'!$B$31)-'03 Assumptions'!$F$13 -> 77.898446 | G30: =G23+(('08 Debt Schedule'!I28+'08 Debt Schedule'!I29)*G23/'09 Operating Model'!I18)+(-'03 Assumptions'!$B$34*MAX(0,G23+('09 Operating Model'!I10*G23/'09 Operating Model'!I18)-MIN((('03 Assumptions'!$B$26+'03 Assumptions'!$B$27)*G36+'03 Assumptions'!$B$28*G43+'03 Assumptions'!$B$29*'06 Sources & Uses'!$B$16+'03 Assumptions'!$B$30*'03 Assumptions'!$B$31),'03 Assumptions'!$B$45*G23)))-(('03 Assumptions'!$B$26+'03 Assumptions'!$B$27)*G36+'03 Assumptions'!$B$28*G43+'03 Assumptions'!$B$29*'06 Sources & Uses'!$B$16+'03 Assumptions'!$B$30*'03 Assumptions'!$B$31)-'03 Assumptions'!$F$13 -> 136.13467
A31: FCF pre-amort 2030 | C31: =C24+(('08 Debt Schedule'!J28+'08 Debt Schedule'!J29)*C24/'09 Operating Model'!J18)+(-'03 Assumptions'!$B$34*MAX(0,C24+('09 Operating Model'!J10*C24/'09 Operating Model'!J18)-MIN((('03 Assumptions'!$B$26+'03 Assumptions'!$B$27)*C37+'03 Assumptions'!$B$28*C44+'03 Assumptions'!$B$29*'06 Sources & Uses'!$B$16+'03 Assumptions'!$B$30*'03 Assumptions'!$B$31),'03 Assumptions'!$B$45*C24)))-(('03 Assumptions'!$B$26+'03 Assumptions'!$B$27)*C37+'03 Assumptions'!$B$28*C44+'03 Assumptions'!$B$29*'06 Sources & Uses'!$B$16+'03 Assumptions'!$B$30*'03 Assumptions'!$B$31)-'03 Assumptions'!$F$13 -> -52.621833 | D31: =D24+(('08 Debt Schedule'!J28+'08 Debt Schedule'!J29)*D24/'09 Operating Model'!J18)+(-'03 Assumptions'!$B$34*MAX(0,D24+('09 Operating Model'!J10*D24/'09 Operating Model'!J18)-MIN((('03 Assumptions'!$B$26+'03 Assumptions'!$B$27)*D37+'03 Assumptions'!$B$28*D44+'03 Assumptions'!$B$29*'06 Sources & Uses'!$B$16+'03 Assumptions'!$B$30*'03 Assumptions'!$B$31),'03 Assumptions'!$B$45*D24)))-(('03 Assumptions'!$B$26+'03 Assumptions'!$B$27)*D37+'03 Assumptions'!$B$28*D44+'03 Assumptions'!$B$29*'06 Sources & Uses'!$B$16+'03 Assumptions'!$B$30*'03 Assumptions'!$B$31)-'03 Assumptions'!$F$13 -> 19.500639 | E31: =E24+(('08 Debt Schedule'!J28+'08 Debt Schedule'!J29)*E24/'09 Operating Model'!J18)+(-'03 Assumptions'!$B$34*MAX(0,E24+('09 Operating Model'!J10*E24/'09 Operating Model'!J18)-MIN((('03 Assumptions'!$B$26+'03 Assumptions'!$B$27)*E37+'03 Assumptions'!$B$28*E44+'03 Assumptions'!$B$29*'06 Sources & Uses'!$B$16+'03 Assumptions'!$B$30*'03 Assumptions'!$B$31),'03 Assumptions'!$B$45*E24)))-(('03 Assumptions'!$B$26+'03 Assumptions'!$B$27)*E37+'03 Assumptions'!$B$28*E44+'03 Assumptions'!$B$29*'06 Sources & Uses'!$B$16+'03 Assumptions'!$B$30*'03 Assumptions'!$B$31)-'03 Assumptions'!$F$13 -> 95.906255 | F31: =F24+(('08 Debt Schedule'!J28+'08 Debt Schedule'!J29)*F24/'09 Operating Model'!J18)+(-'03 Assumptions'!$B$34*MAX(0,F24+('09 Operating Model'!J10*F24/'09 Operating Model'!J18)-MIN((('03 Assumptions'!$B$26+'03 Assumptions'!$B$27)*F37+'03 Assumptions'!$B$28*F44+'03 Assumptions'!$B$29*'06 Sources & Uses'!$B$16+'03 Assumptions'!$B$30*'03 Assumptions'!$B$31),'03 Assumptions'!$B$45*F24)))-(('03 Assumptions'!$B$26+'03 Assumptions'!$B$27)*F37+'03 Assumptions'!$B$28*F44+'03 Assumptions'!$B$29*'06 Sources & Uses'!$B$16+'03 Assumptions'!$B$30*'03 Assumptions'!$B$31)-'03 Assumptions'!$F$13 -> 176.76132 | G31: =G24+(('08 Debt Schedule'!J28+'08 Debt Schedule'!J29)*G24/'09 Operating Model'!J18)+(-'03 Assumptions'!$B$34*MAX(0,G24+('09 Operating Model'!J10*G24/'09 Operating Model'!J18)-MIN((('03 Assumptions'!$B$26+'03 Assumptions'!$B$27)*G37+'03 Assumptions'!$B$28*G44+'03 Assumptions'!$B$29*'06 Sources & Uses'!$B$16+'03 Assumptions'!$B$30*'03 Assumptions'!$B$31),'03 Assumptions'!$B$45*G24)))-(('03 Assumptions'!$B$26+'03 Assumptions'!$B$27)*G37+'03 Assumptions'!$B$28*G44+'03 Assumptions'!$B$29*'06 Sources & Uses'!$B$16+'03 Assumptions'!$B$30*'03 Assumptions'!$B$31)-'03 Assumptions'!$F$13 -> 265.50463
A32: FCF pre-amort 2031 | C32: =C25+(('08 Debt Schedule'!K28+'08 Debt Schedule'!K29)*C25/'09 Operating Model'!K18)+(-'03 Assumptions'!$B$34*MAX(0,C25+('09 Operating Model'!K10*C25/'09 Operating Model'!K18)-MIN((('03 Assumptions'!$B$26+'03 Assumptions'!$B$27)*C38+'03 Assumptions'!$B$28*C45+'03 Assumptions'!$B$29*'06 Sources & Uses'!$B$16+'03 Assumptions'!$B$30*'03 Assumptions'!$B$31),'03 Assumptions'!$B$45*C25)))-(('03 Assumptions'!$B$26+'03 Assumptions'!$B$27)*C38+'03 Assumptions'!$B$28*C45+'03 Assumptions'!$B$29*'06 Sources & Uses'!$B$16+'03 Assumptions'!$B$30*'03 Assumptions'!$B$31)-'03 Assumptions'!$F$13 -> -29.16699 | D32: =D25+(('08 Debt Schedule'!K28+'08 Debt Schedule'!K29)*D25/'09 Operating Model'!K18)+(-'03 Assumptions'!$B$34*MAX(0,D25+('09 Operating Model'!K10*D25/'09 Operating Model'!K18)-MIN((('03 Assumptions'!$B$26+'03 Assumptions'!$B$27)*D38+'03 Assumptions'!$B$28*D45+'03 Assumptions'!$B$29*'06 Sources & Uses'!$B$16+'03 Assumptions'!$B$30*'03 Assumptions'!$B$31),'03 Assumptions'!$B$45*D25)))-(('03 Assumptions'!$B$26+'03 Assumptions'!$B$27)*D38+'03 Assumptions'!$B$28*D45+'03 Assumptions'!$B$29*'06 Sources & Uses'!$B$16+'03 Assumptions'!$B$30*'03 Assumptions'!$B$31)-'03 Assumptions'!$F$13 -> 63.69862 | E32: =E25+(('08 Debt Schedule'!K28+'08 Debt Schedule'!K29)*E25/'09 Operating Model'!K18)+(-'03 Assumptions'!$B$34*MAX(0,E25+('09 Operating Model'!K10*E25/'09 Operating Model'!K18)-MIN((('03 Assumptions'!$B$26+'03 Assumptions'!$B$27)*E38+'03 Assumptions'!$B$28*E45+'03 Assumptions'!$B$29*'06 Sources & Uses'!$B$16+'03 Assumptions'!$B$30*'03 Assumptions'!$B$31),'03 Assumptions'!$B$45*E25)))-(('03 Assumptions'!$B$26+'03 Assumptions'!$B$27)*E38+'03 Assumptions'!$B$28*E45+'03 Assumptions'!$B$29*'06 Sources & Uses'!$B$16+'03 Assumptions'!$B$30*'03 Assumptions'!$B$31)-'03 Assumptions'!$F$13 -> 164.90513 | F32: =F25+(('08 Debt Schedule'!K28+'08 Debt Schedule'!K29)*F25/'09 Operating Model'!K18)+(-'03 Assumptions'!$B$34*MAX(0,F25+('09 Operating Model'!K10*F25/'09 Operating Model'!K18)-MIN((('03 Assumptions'!$B$26+'03 Assumptions'!$B$27)*F38+'03 Assumptions'!$B$28*F45+'03 Assumptions'!$B$29*'06 Sources & Uses'!$B$16+'03 Assumptions'!$B$30*'03 Assumptions'!$B$31),'03 Assumptions'!$B$45*F25)))-(('03 Assumptions'!$B$26+'03 Assumptions'!$B$27)*F38+'03 Assumptions'!$B$28*F45+'03 Assumptions'!$B$29*'06 Sources & Uses'!$B$16+'03 Assumptions'!$B$30*'03 Assumptions'!$B$31)-'03 Assumptions'!$F$13 -> 277.7873 | G32: =G25+(('08 Debt Schedule'!K28+'08 Debt Schedule'!K29)*G25/'09 Operating Model'!K18)+(-'03 Assumptions'!$B$34*MAX(0,G25+('09 Operating Model'!K10*G25/'09 Operating Model'!K18)-MIN((('03 Assumptions'!$B$26+'03 Assumptions'!$B$27)*G38+'03 Assumptions'!$B$28*G45+'03 Assumptions'!$B$29*'06 Sources & Uses'!$B$16+'03 Assumptions'!$B$30*'03 Assumptions'!$B$31),'03 Assumptions'!$B$45*G25)))-(('03 Assumptions'!$B$26+'03 Assumptions'!$B$27)*G38+'03 Assumptions'!$B$28*G45+'03 Assumptions'!$B$29*'06 Sources & Uses'!$B$16+'03 Assumptions'!$B$30*'03 Assumptions'!$B$31)-'03 Assumptions'!$F$13 -> 402.71517
A35: TLB-EUR end 2027 | C35: ='06 Sources & Uses'!$B$14-MIN('06 Sources & Uses'!$B$14,'06 Sources & Uses'!$B$14*'03 Assumptions'!$B$38)-MIN('06 Sources & Uses'!$B$14-MIN('06 Sources & Uses'!$B$14,'06 Sources & Uses'!$B$14*'03 Assumptions'!$B$38),MAX(0,C28-MIN('06 Sources & Uses'!$B$14,'06 Sources & Uses'!$B$14*'03 Assumptions'!$B$38)-MIN('06 Sources & Uses'!$B$15,'06 Sources & Uses'!$B$15*'03 Assumptions'!$B$38))) -> 1514.7 | D35: ='06 Sources & Uses'!$B$14-MIN('06 Sources & Uses'!$B$14,'06 Sources & Uses'!$B$14*'03 Assumptions'!$B$38)-MIN('06 Sources & Uses'!$B$14-MIN('06 Sources & Uses'!$B$14,'06 Sources & Uses'!$B$14*'03 Assumptions'!$B$38),MAX(0,D28-MIN('06 Sources & Uses'!$B$14,'06 Sources & Uses'!$B$14*'03 Assumptions'!$B$38)-MIN('06 Sources & Uses'!$B$15,'06 Sources & Uses'!$B$15*'03 Assumptions'!$B$38))) -> 1514.7 | E35: ='06 Sources & Uses'!$B$14-MIN('06 Sources & Uses'!$B$14,'06 Sources & Uses'!$B$14*'03 Assumptions'!$B$38)-MIN('06 Sources & Uses'!$B$14-MIN('06 Sources & Uses'!$B$14,'06 Sources & Uses'!$B$14*'03 Assumptions'!$B$38),MAX(0,E28-MIN('06 Sources & Uses'!$B$14,'06 Sources & Uses'!$B$14*'03 Assumptions'!$B$38)-MIN('06 Sources & Uses'!$B$15,'06 Sources & Uses'!$B$15*'03 Assumptions'!$B$38))) -> 1514.7 | F35: ='06 Sources & Uses'!$B$14-MIN('06 Sources & Uses'!$B$14,'06 Sources & Uses'!$B$14*'03 Assumptions'!$B$38)-MIN('06 Sources & Uses'!$B$14-MIN('06 Sources & Uses'!$B$14,'06 Sources & Uses'!$B$14*'03 Assumptions'!$B$38),MAX(0,F28-MIN('06 Sources & Uses'!$B$14,'06 Sources & Uses'!$B$14*'03 Assumptions'!$B$38)-MIN('06 Sources & Uses'!$B$15,'06 Sources & Uses'!$B$15*'03 Assumptions'!$B$38))) -> 1514.7 | G35: ='06 Sources & Uses'!$B$14-MIN('06 Sources & Uses'!$B$14,'06 Sources & Uses'!$B$14*'03 Assumptions'!$B$38)-MIN('06 Sources & Uses'!$B$14-MIN('06 Sources & Uses'!$B$14,'06 Sources & Uses'!$B$14*'03 Assumptions'!$B$38),MAX(0,G28-MIN('06 Sources & Uses'!$B$14,'06 Sources & Uses'!$B$14*'03 Assumptions'!$B$38)-MIN('06 Sources & Uses'!$B$15,'06 Sources & Uses'!$B$15*'03 Assumptions'!$B$38))) -> 1514.7
A36: TLB-EUR end 2028 | C36: =C35-MIN(C35,'06 Sources & Uses'!$B$14*'03 Assumptions'!$B$38)-MIN(C35-MIN(C35,'06 Sources & Uses'!$B$14*'03 Assumptions'!$B$38),MAX(0,C29-MIN(C35,'06 Sources & Uses'!$B$14*'03 Assumptions'!$B$38)-MIN(C42,'06 Sources & Uses'!$B$15*'03 Assumptions'!$B$38))) -> 1499.4 | D36: =D35-MIN(D35,'06 Sources & Uses'!$B$14*'03 Assumptions'!$B$38)-MIN(D35-MIN(D35,'06 Sources & Uses'!$B$14*'03 Assumptions'!$B$38),MAX(0,D29-MIN(D35,'06 Sources & Uses'!$B$14*'03 Assumptions'!$B$38)-MIN(D42,'06 Sources & Uses'!$B$15*'03 Assumptions'!$B$38))) -> 1499.4 | E36: =E35-MIN(E35,'06 Sources & Uses'!$B$14*'03 Assumptions'!$B$38)-MIN(E35-MIN(E35,'06 Sources & Uses'!$B$14*'03 Assumptions'!$B$38),MAX(0,E29-MIN(E35,'06 Sources & Uses'!$B$14*'03 Assumptions'!$B$38)-MIN(E42,'06 Sources & Uses'!$B$15*'03 Assumptions'!$B$38))) -> 1499.4 | F36: =F35-MIN(F35,'06 Sources & Uses'!$B$14*'03 Assumptions'!$B$38)-MIN(F35-MIN(F35,'06 Sources & Uses'!$B$14*'03 Assumptions'!$B$38),MAX(0,F29-MIN(F35,'06 Sources & Uses'!$B$14*'03 Assumptions'!$B$38)-MIN(F42,'06 Sources & Uses'!$B$15*'03 Assumptions'!$B$38))) -> 1499.4 | G36: =G35-MIN(G35,'06 Sources & Uses'!$B$14*'03 Assumptions'!$B$38)-MIN(G35-MIN(G35,'06 Sources & Uses'!$B$14*'03 Assumptions'!$B$38),MAX(0,G29-MIN(G35,'06 Sources & Uses'!$B$14*'03 Assumptions'!$B$38)-MIN(G42,'06 Sources & Uses'!$B$15*'03 Assumptions'!$B$38))) -> 1499.4
A37: TLB-EUR end 2029 | C37: =C36-MIN(C36,'06 Sources & Uses'!$B$14*'03 Assumptions'!$B$38)-MIN(C36-MIN(C36,'06 Sources & Uses'!$B$14*'03 Assumptions'!$B$38),MAX(0,C30-MIN(C36,'06 Sources & Uses'!$B$14*'03 Assumptions'!$B$38)-MIN(C43,'06 Sources & Uses'!$B$15*'03 Assumptions'!$B$38))) -> 1484.1 | D37: =D36-MIN(D36,'06 Sources & Uses'!$B$14*'03 Assumptions'!$B$38)-MIN(D36-MIN(D36,'06 Sources & Uses'!$B$14*'03 Assumptions'!$B$38),MAX(0,D30-MIN(D36,'06 Sources & Uses'!$B$14*'03 Assumptions'!$B$38)-MIN(D43,'06 Sources & Uses'!$B$15*'03 Assumptions'!$B$38))) -> 1484.1 | E37: =E36-MIN(E36,'06 Sources & Uses'!$B$14*'03 Assumptions'!$B$38)-MIN(E36-MIN(E36,'06 Sources & Uses'!$B$14*'03 Assumptions'!$B$38),MAX(0,E30-MIN(E36,'06 Sources & Uses'!$B$14*'03 Assumptions'!$B$38)-MIN(E43,'06 Sources & Uses'!$B$15*'03 Assumptions'!$B$38))) -> 1484.1 | F37: =F36-MIN(F36,'06 Sources & Uses'!$B$14*'03 Assumptions'!$B$38)-MIN(F36-MIN(F36,'06 Sources & Uses'!$B$14*'03 Assumptions'!$B$38),MAX(0,F30-MIN(F36,'06 Sources & Uses'!$B$14*'03 Assumptions'!$B$38)-MIN(F43,'06 Sources & Uses'!$B$15*'03 Assumptions'!$B$38))) -> 1484.1 | G37: =G36-MIN(G36,'06 Sources & Uses'!$B$14*'03 Assumptions'!$B$38)-MIN(G36-MIN(G36,'06 Sources & Uses'!$B$14*'03 Assumptions'!$B$38),MAX(0,G30-MIN(G36,'06 Sources & Uses'!$B$14*'03 Assumptions'!$B$38)-MIN(G43,'06 Sources & Uses'!$B$15*'03 Assumptions'!$B$38))) -> 1428.2145
A38: TLB-EUR end 2030 | C38: =C37-MIN(C37,'06 Sources & Uses'!$B$14*'03 Assumptions'!$B$38)-MIN(C37-MIN(C37,'06 Sources & Uses'!$B$14*'03 Assumptions'!$B$38),MAX(0,C31-MIN(C37,'06 Sources & Uses'!$B$14*'03 Assumptions'!$B$38)-MIN(C44,'06 Sources & Uses'!$B$15*'03 Assumptions'!$B$38))) -> 1468.8 | D38: =D37-MIN(D37,'06 Sources & Uses'!$B$14*'03 Assumptions'!$B$38)-MIN(D37-MIN(D37,'06 Sources & Uses'!$B$14*'03 Assumptions'!$B$38),MAX(0,D31-MIN(D37,'06 Sources & Uses'!$B$14*'03 Assumptions'!$B$38)-MIN(D44,'06 Sources & Uses'!$B$15*'03 Assumptions'!$B$38))) -> 1468.8 | E38: =E37-MIN(E37,'06 Sources & Uses'!$B$14*'03 Assumptions'!$B$38)-MIN(E37-MIN(E37,'06 Sources & Uses'!$B$14*'03 Assumptions'!$B$38),MAX(0,E31-MIN(E37,'06 Sources & Uses'!$B$14*'03 Assumptions'!$B$38)-MIN(E44,'06 Sources & Uses'!$B$15*'03 Assumptions'!$B$38))) -> 1453.1429 | F38: =F37-MIN(F37,'06 Sources & Uses'!$B$14*'03 Assumptions'!$B$38)-MIN(F37-MIN(F37,'06 Sources & Uses'!$B$14*'03 Assumptions'!$B$38),MAX(0,F31-MIN(F37,'06 Sources & Uses'!$B$14*'03 Assumptions'!$B$38)-MIN(F44,'06 Sources & Uses'!$B$15*'03 Assumptions'!$B$38))) -> 1372.2879 | G38: =G37-MIN(G37,'06 Sources & Uses'!$B$14*'03 Assumptions'!$B$38)-MIN(G37-MIN(G37,'06 Sources & Uses'!$B$14*'03 Assumptions'!$B$38),MAX(0,G31-MIN(G37,'06 Sources & Uses'!$B$14*'03 Assumptions'!$B$38)-MIN(G44,'06 Sources & Uses'!$B$15*'03 Assumptions'!$B$38))) -> 1227.6591
A39: TLB-EUR end 2031 | C39: =C38-MIN(C38,'06 Sources & Uses'!$B$14*'03 Assumptions'!$B$38)-MIN(C38-MIN(C38,'06 Sources & Uses'!$B$14*'03 Assumptions'!$B$38),MAX(0,C32-MIN(C38,'06 Sources & Uses'!$B$14*'03 Assumptions'!$B$38)-MIN(C45,'06 Sources & Uses'!$B$15*'03 Assumptions'!$B$38))) -> 1453.5 | D39: =D38-MIN(D38,'06 Sources & Uses'!$B$14*'03 Assumptions'!$B$38)-MIN(D38-MIN(D38,'06 Sources & Uses'!$B$14*'03 Assumptions'!$B$38),MAX(0,D32-MIN(D38,'06 Sources & Uses'!$B$14*'03 Assumptions'!$B$38)-MIN(D45,'06 Sources & Uses'!$B$15*'03 Assumptions'!$B$38))) -> 1453.5 | E39: =E38-MIN(E38,'06 Sources & Uses'!$B$14*'03 Assumptions'!$B$38)-MIN(E38-MIN(E38,'06 Sources & Uses'!$B$14*'03 Assumptions'!$B$38),MAX(0,E32-MIN(E38,'06 Sources & Uses'!$B$14*'03 Assumptions'!$B$38)-MIN(E45,'06 Sources & Uses'!$B$15*'03 Assumptions'!$B$38))) -> 1353.187 | F39: =F38-MIN(F38,'06 Sources & Uses'!$B$14*'03 Assumptions'!$B$38)-MIN(F38-MIN(F38,'06 Sources & Uses'!$B$14*'03 Assumptions'!$B$38),MAX(0,F32-MIN(F38,'06 Sources & Uses'!$B$14*'03 Assumptions'!$B$38)-MIN(F45,'06 Sources & Uses'!$B$15*'03 Assumptions'!$B$38))) -> 1159.4498 | G39: =G38-MIN(G38,'06 Sources & Uses'!$B$14*'03 Assumptions'!$B$38)-MIN(G38-MIN(G38,'06 Sources & Uses'!$B$14*'03 Assumptions'!$B$38),MAX(0,G32-MIN(G38,'06 Sources & Uses'!$B$14*'03 Assumptions'!$B$38)-MIN(G45,'06 Sources & Uses'!$B$15*'03 Assumptions'!$B$38))) -> 889.8931
