Workbook

Sheet 00 Executive Summary
A1: TECHNOGYM S.p.A. (BIT: TGYM) - DCF EXECUTIVE SUMMARY | v2.0 | 17 JULY 2026
A3: THE ANSWER
A4: Base-case fair value (Gordon TV): | B4: ='11 DCF Valuation'!B27
A5: Cross-check (exit-multiple TV): | B5: ='11 DCF Valuation'!B31
A6: Current price (08-Jul-26): | B6: ='11 DCF Valuation'!B28
A7: Upside / (downside): | B7: ='11 DCF Valuation'!B29
A8: Scenario range (full model, recorded 16-Jul-26): | B8: Bear EUR 8.82 | C8: Bull EUR 24.05 | D8: (re-run switch on 03 Assumptions to refresh)
A10: WHAT DRIVES THE VALUE
A11: 1. BtoB growth path (81% of revenue): base fades 9% → 2.5% by 2035; every 1pp ≈ €2.5–2.9m EBITDA at incremental margins.
A12: 2. EBITDA margin endpoint: 21.6% today → 23.5% base by 2032. Four consecutive years of expansion support it; bear case tests a stall.
A13: 3. Digital is an OPTION, not the base: est. €45m (4.4% of revenue) today, ~7% by 2035 in base. Bull case (attach 20%→40%) is what consensus prices.
A15: KEY ASSUMPTIONS (speed-read — full detail on 03)
A16: Revenue CAGR 2026-35 | B16: =('05 Revenue Build'!O27/'05 Revenue Build'!E27)^(1/10)-1
A17: EBITDA margin endpoint | B17: ='03 Assumptions'!F13
A18: Terminal growth g | B18: ='03 Assumptions'!F16
A19: WACC | B19: ='10 WACC'!B15
A20: Exit multiple (cross-check) | B20: ='03 Assumptions'!F17
A21: Tax rate | B21: ='03 Assumptions'!B21
A22: TV % of EV | B22: ='11 DCF Valuation'!B32
A24: BRIDGE TO CONSENSUS (why we differ from the Street's €19.3 avg TP)
A25: Consensus average TP | B25: 19.3
A26: Our base-case DCF | B26: ='11 DCF Valuation'!B27
A27: Gap | B27: =B26-B25
A28: Attribution (analyst estimates, blue):
A29: Margin endpoint (Street ~24.5% vs our 23.5% total) | B29: -1.6
A30: Digital ramp (Street implicitly faster / higher attach) | B30: -1.2
A31: Growth path + WACC/terminal (residual) | B31: -0.78
A32: =IF(ABS(B29+B30+B31-B27)<0.5,"CHECK OK: attribution ties to gap","CHECK: attribution does not tie")
A34: FOOTBALL FIELD — value per share (€)
A35: Method | B35: Low | C35: High | D35: Range
A36: 52-week trading range | B36: 11 | C36: 21.82 | D36: =C36-B36 | E36: <- Current EUR 15.19 and DCF base EUR 15.72 fall inside every range except the bear-scenario tail.
A37: Comps 10.5x-14x 2026E EBITDA | B37: =(10.5*'06 Operating Model'!F6+'03 Assumptions'!B24)/'03 Assumptions'!B23 | C37: =(14*'06 Operating Model'!F6+'03 Assumptions'!B24)/'03 Assumptions'!B23 | D37: =C37-B37
A38: DCF grid (WACC 7-8.5% x g) | B38: =MIN('12 Sensitivity Analysis'!C6:G11) | C38: =MAX('12 Sensitivity Analysis'!C6:G11) | D38: =C38-B38
A39: DCF scenarios Bear-Bull | B39: 8.82 | C39: 22.42 | D39: =C39-B39
A40: Consensus TP range | B40: 16 | C40: 26.25 | D40: =C40-B40
A41: Current price | B41: ='11 DCF Valuation'!B28
A44: HOW TO USE THIS MODEL
A45: 1. Scenario switch: edit '03 Assumptions'!B3 (1=Bear, 2=Base, 3=Bull). Everything recalculates.
A46: 2. BLUE cells are editable inputs; BLACK are formulas; GREEN are cross-sheet links; RED are checks.
A47: 3. If any RED check cell reads ERROR, stop and review before trusting outputs.
...

Sheet 01 Cover
A1: TECHNOGYM S.p.A. — DCF MODEL
A2: TECHNOGYM S.p.A. (BIT: TGYM)
A3: Discounted Cash Flow Valuation — Institutional Model
A5: Investment question: Can Technogym transition from premium fitness equipment
A6: manufacturer to a recurring software & connected wellness platform deserving software multiples?
A8: Prepared: 17 July 2026 | v2.0 (partner revision round) | Analyst: Tanmay Gambhir | EUR millions
A10: Sheet map:
A11: 02 Sources | D11: Every figure traced: source, date, confidence
A12: 03 Assumptions | D12: ALL editable inputs (blue). Scenario switch drives the model
A13: 04 Historical Financials | D13: FY2022–25 reported (company PRs)
A14: 05 Revenue Build | D14: Driver-based: BtoB / BtoC / digital estimation block
A15: 06 Operating Model | D15: Margins → EBITDA → EBIT → NOPAT
A16: 07 Working Capital | D16: NWC % revenue method
A17: 08 Capex & Depreciation | D17: % revenue with normalisation
A18: 09 Free Cash Flow | D18: FCFF bridge
A19: 10 WACC | D19: Bund-based build (no CRP double-count)
A20: 11 DCF Valuation | D20: Gordon + exit-multiple cross-check
A21: 12 Sensitivity Analysis | D21: WACC×g, WACC×exit, margin×growth
A22: 13 Scenarios | D22: Bear/Base/Bull side-by-side (simplified engine)
A23: 14 Charts & Dashboard | D23: Outputs + charts
A26: Color code: BLUE = input (edit me) | BLACK = formula | GREEN = cross-sheet link | RED = check
A27: Legend: yellow-filled cells are the primary levers to edit (scenario switch, key assumptions).

Sheet 02 Sources
A1: SOURCE REGISTER
A3: Item | B3: Value | C3: Confidence | D3: Source / date
A4: FY2025 revenue / EBITDA adj / NP adj | B4: 1,019.3 / 220.1 / 119.9 | C4: H | D4: Technogym FY25 results PR, 19-Mar-2026 (corporate.technogym.com)
A5: Segment splits, geography, channels | B5: see 04 | C5: H | D5: FY25 PR tables
A6: FY2022-24 revenue & EBITDA | B6: 721.5/808.1/901.3; 132/152/178.4 | C6: H | D6: FY23 & FY25 PRs
A7: Net financial position (incl IFRS16) | B7: +156.0 | C7: H | D7: FY25 PR
A8: Shares out (ex-treasury) | B8: 199.3m | C8: H | D8: FY25 PR: 201.3m total less 2.036m treasury
A9: Share price | B9: 15.19 (08-Jul-26) | C9: H | D9: Investing.com
A10: Q1 2026 revenue | B10: 236.8 (+10.1%) | C10: H | D10: Q1-26 IR presentation, 6-May-26
A11: Bund 10Y | B11: 3.13% | C11: H | D11: TradingEconomics 16-Jul-26
A12: Mature ERP / Italy CRP | B12: 4.23% / 2.46% | C12: H | D12: Damodaran, Jan-2026 update
A13: Beta (levered) | B13: 0.95 triangulated | C13: M | D13: Yahoo 0.86 5Y-M; TradingView 0.94; range 0.80-1.16
A14: Digital revenue 2025 | B14: ~45 (ESTIMATE) | C14: L | D14: Estimation block: 100k sites/500k homes x attach x ARPU. NOT DISCLOSED by company
... A19: All scenario growth/margin paths | B19: 03 Assumptions | C19: L/M | D19: Analyst judgment anchored to history - see Assumptions Register (project 01_Research)
A22: Confidence: H = reported/primary | M = derived/consensus | L = analyst estimate (clearly labelled)
A24: ANNOTATED-SCREENSHOT NOTE: source-page screenshots are not embedded (build environment cannot capture
A25: annotated images from the source PDFs). In lieu: precise table-level citations below. All primary PDFs are linked
A26: in the project Bibliography for page-level verification.
A28: Precise citations:
A29: Revenue by customer type | D29: FY25 PR p.3, table 'Revenue by customer type'
A30: Revenue by geography | D30: FY25 PR p.3-4, table 'Revenue by geographies'
A31: Revenue by channel | D31: FY25 PR p.4, table 'Revenue by distribution channels'
A32: EBITDA / EBIT / NP adj. | D32: FY25 PR p.4-5, section 2
A33: NFP & FCF | D33: FY25 PR p.5, 'Net Financial Position and Free Cash Flow'
A34: Full P&L / BS / CF | D34: FY25 PR p.10-12, consolidated statements
A35: Margin history 2021-24 | D35: FY25 PR p.2 (17.5/18.3/18.8/19.8%)

Sheet 03 Assumptions
A1: ASSUMPTIONS & SCENARIO SWITCH
A3: SCENARIO SWITCH (1=Bear, 2=Base, 3=Bull) | B3: 2 | C3: =IF(OR($B$3=1,$B$3=2,$B$3=3),"OK","ERROR: switch must be 1, 2 or 3")
A5: Scenario-driven inputs | C5: Bear | D5: Base | E5: Bull | F5: ACTIVE
A6: BtoB equipment growth, 2026 | C6: 0.04 | D6: 0.09 | E6: 0.13 | F6: =CHOOSE($B$3,C6,D6,E6)
A7: BtoB growth by 2035 (fade to) | C7: 0.02 | D7: 0.025 | E7: 0.03 | F7: =CHOOSE($B$3,C7,D7,E7)
A8: BtoC growth, 2026 | C8: 0 | D8: 0.05 | E8: 0.09 | F8: =CHOOSE($B$3,C8,D8,E8)
A9: BtoC growth by 2035 (fade to) | C9: 0.01 | D9: 0.02 | E9: 0.025 | F9: =CHOOSE($B$3,C9,D9,E9)
A10: B2B digital attach endpoint (by 2030) | C10: 0.2 | D10: 0.3 | E10: 0.4 | F10: =CHOOSE($B$3,C10,D10,E10)
A11: Consumer digital attach endpoint (by 2030) | C11: 0.15 | D11: 0.2 | E11: 0.3 | F11: =CHOOSE($B$3,C11,D11,E11)
A12: Digital ARPU growth p.a. | C12: 0 | D12: 0.03 | E12: 0.05 | F12: =CHOOSE($B$3,C12,D12,E12)
A13: Hardware EBITDA margin endpoint by 2032 (v3 isolated; ex-digital) | C13: 0.195 | D13: 0.2075 | E13: 0.222 | F13: =CHOOSE($B$3,C13,D13,E13)
A14: Capex % revenue | C14: 0.055 | D14: 0.05 | E14: 0.05 | F14: =CHOOSE($B$3,C14,D14,E14)
A15: WC stress: DSO shift (+days, bear case) | C15: 10 | D15: 0 | E15: 0 | F15: =CHOOSE($B$3,C15,D15,E15)
A16: Terminal growth g | C16: 0.015 | D16: 0.0225 | E16: 0.0275 | F16: =CHOOSE($B$3,C16,D16,E16)
A17: Exit EV/EBITDA multiple (cross-check) | C17: 10 | D17: 12 | E17: 14 | F17: =CHOOSE($B$3,C17,D17,E17)
A18: Digital EBITDA margin (v3; editable, sensitize 50-75%) | C18: 0.5 | D18: 0.6 | E18: 0.75 | F18: =CHOOSE($B$3,C18,D18,E18)
A20: Fixed inputs (edit if evidence changes)
A21: Effective tax rate | B21: 0.274
A22: D&A % revenue | B22: 0.051
A23: Shares outstanding ex-treasury (m) | B23: 199.3
A24: Net financial position incl IFRS16 (€m, + = net cash) | B24: 156
A25: Share price (08-Jul-26, €) | B25: 15.19
A26: B2B installed sites (2025) | B26: 100000
A27: B2B sites growth p.a. | B27: 0.03
A28: B2B digital ARPU €/site/yr (2025) | B28: 1800
A29: Consumer connected homes (2025) | B29: 500000
A30: Homes growth p.a. | B30: 0.05
A31: Consumer ARPU €/user/yr (2025) | B31: 120
A32: B2B attach rate 2025 (est.) | B32: 0.2
... A36: 2025 digital revenue est. (€m) | B36: 45
A38: Note: digital revenue is NOT disclosed. Rows 26-33 + 36 are an explicit L-confidence estimation
A39: block; 2025 segment bases (rows 34-35) are reported segments minus the digital estimate.
A40: =IF(ABS(B34+B35+B36-1019.3)<0.5,"CHECK OK: 2025 splits sum to reported 1,019.3","ERROR: 2025 revenue splits do not sum")
A42: IFRS 16 & working-capital inputs (v2)
A43: Lease principal repayment % revenue (2025: 15.1/1019.3) | B43: 0.0148
A44: NFP EXCLUDING IFRS16 (€m) — used in DCF bridge | B44: 209.6
A45: DSO days (2025 actual) | B45: 47.3
A46: DIO days on materials (2025 actual) | B46: 127
A47: DPO days on materials (2025 actual) | B47: 221
A48: Materials cost % revenue | B48: 0.315
...

Sheet 04 Historical Financials
A1: HISTORICAL FINANCIALS & TRENDS
A3: €m | B3: 2022 | C3: 2023 | D3: 2024 | E3: 2025
A4: Revenue | B4: 721.5 | C4: 808.1 | D4: 901.3 | E4: 1019.3
A5: Adj. EBITDA | B5: 132 | C5: 152 | D5: 178.4 | E5: 220.1
A6: Adj. EBIT | D6: 122.1 | E6: 163.9
A7: Adj. Net profit | D7: 90.2 | E7: 119.9
A8: D&A | D8: 51.8 | E8: 52.3
A9: Recurring FCF | D9: 116.4 | E9: 129.9
A10: Net financial position (+=cash) | D10: 160.1 | E10: 156
A11: Inventory | D11: 110.9 | E11: 112
A12: Trade receivables | D12: 132.8 | E12: 131.8
A13: Trade payables | D13: 179.1 | E13: 194.4
A15: Derived ratios
A16: EBITDA margin | B16: =B5/B4 | C16: =C5/C4 | D16: =D5/D4 | E16: =E5/E4
A17: Revenue growth | C17: =C4/B4-1 | D17: =D4/C4-1 | E17: =E4/D4-1
A18: Net trade WC (inv+AR-AP) | D18: =D11+D12-D13 | E18: =E11+E12-E13
A19: NWC % revenue | D19: =D18/D4 | E19: =E18/E4
A21: Source: FY2023 & FY2025 results press releases (see 02 Sources). Blue = reported hardcodes.
A23: TREND EXHIBITS
A24: EBITDA margin 2021-2025 (reported)
A25: Year | B25: 2021 | C25: 2022 | D25: 2023 | E25: 2024 | F25: 2025
A26: Margin | B26: 0.175 | C26: 0.183 | D26: 0.188 | E26: 0.198 | F26: 0.216
A28: Segment & geography mix (reported, €m)
B29: 2024 | C29: 2025
A30: BtoB | B30: 716.9 | C30: 823.6
A31: BtoC | B31: 184.4 | C31: 195.7
A32: Europe ex-Italy | B32: 416.1 | C32: 479.7
A33: Americas | B33: 146.4 | C33: 168.2
A34: MEIA | B34: 126.4 | C34: 134.7
A35: APAC | B35: 122.2 | C35: 128.7
A36: Italy | B36: 90.1 | C36: 108
A38: Cash conversion (recurring pre-tax FCF / EBITDA): 86% (2024) → 82% (2025). ROCE ≈ 24% (2025, approx).
A40: H1-2026 INTERIM CHECKPOINT (unaudited, vs H1-2025) — added 03-Sep-2026
B41: H1 2026 | C41: H1 2025 | D41: % chg / delta
A42: Revenue | B42: 492.6 | C42: 458.8 | D42: =B42/C42-1
A43: Americas revenue | B43: 76.2 | C43: 77 | D43: =B43/C43-1
A44: Adj. EBITDA | B44: 85.7 | C44: 84.8 | D44: =B44/C44-1
A45: Adj. EBITDA margin | B45: =B44/B42 | C45: =C44/C42 | D45: =B45-C45
A46: Recurring FCF (pre-tax) | B46: 20 | C46: 44.2 | D46: =B46/C46-1
A47: Digital/MyWellness KPI disclosure: none (unchanged).
...

Sheet 05 Revenue Build
A1: REVENUE BUILD
A3: €m unless noted | B3: 2022A | C3: 2023A | D3: 2024A | E3: 2025A | F3: 2026E | G3: 2027E | H3: 2028E | I3: 2029E | J3: 2030E | K3: 2031E | L3: 2032E | M3: 2033E | N3: 2034E | O3: 2035E
A4: Year index (t) | F4: 1 | G4: 2 | H4: 3 | I4: 4 | J4: 5 | K4: 6 | L4: 7 | M4: 8 | N4: 9 | O4: 10
A6: BtoB equipment & services (ex-digital)
A7: Growth (base/bull: linear fade; bear: explicit cyclical path row 32) | F7: =IF('03 Assumptions'!$B$3=1,F32,'03 Assumptions'!$F$6+('03 Assumptions'!$F$7-'03 Assumptions'!$F$6)*(F4-1)/9) | G7: =IF('03 Assumptions'!$B$3=1,G32,'03 Assumptions'!$F$6+('03 Assumptions'!$F$7-'03 Assumptions'!$F$6)*(G4-1)/9) | H7: =IF('03 Assumptions'!$B$3=1,H32,'03 Assumptions'!$F$6+('03 Assumptions'!$F$7-'03 Assumptions'!$F$6)*(H4-1)/9) | I7: =IF('03 Assumptions'!$B$3=1,I32,'03 Assumptions'!$F$6+('03 Assumptions'!$F$7-'03 Assumptions'!$F$6)*(I4-1)/9) | J7: =IF('03 Assumptions'!$B$3=1,J32,'03 Assumptions'!$F$6+('03 Assumptions'!$F$7-'03 Assumptions'!$F$6)*(J4-1)/9) | K7: =IF('03 Assumptions'!$B$3=1,K32,'03 Assumptions'!$F$6+('03 Assumptions'!$F$7-'03 Assumptions'!$F$6)*(K4-1)/9) | L7: =IF('03 Assumptions'!$B$3=1,L32,'03 Assumptions'!$F$6+('03 Assumptions'!$F$7-'03 Assumptions'!$F$6)*(L4-1)/9) | M7: =IF('03 Assumptions'!$B$3=1,M32,'03 Assumptions'!$F$6+('03 Assumptions'!$F$7-'03 Assumptions'!$F$6)*(M4-1)/9) | ... O7: =IF('03 Assumptions'!$B$3=1,O32,'03 Assumptions'!$F$6+('03 Assumptions'!$F$7-'03 Assumptions'!$F$6)*(O4-1)/9)
A8: Revenue | E8: ='03 Assumptions'!$B$34 | F8: =E8*(1+F7) | G8: =F8*(1+G7) | H8: =G8*(1+H7) | I8: =H8*(1+I7) | J8: =I8*(1+J7) | K8: =J8*(1+K7) | L8: =K8*(1+L7) | M8: =L8*(1+M7) | ... O8: =N8*(1+O7)
A10: BtoC (ex-digital)
A11: Growth (linear fade) | F11: ='03 Assumptions'!$F$8+('03 Assumptions'!$F$9-'03 Assumptions'!$F$8)*(F4-1)/9 | G11: ='03 Assumptions'!$F$8+('03 Assumptions'!$F$9-'03 Assumptions'!$F$8)*(G4-1)/9 | H11: ='03 Assumptions'!$F$8+('03 Assumptions'!$F$9-'03 Assumptions'!$F$8)*(H4-1)/9 | I11: ='03 Assumptions'!$F$8+('03 Assumptions'!$F$9-'03 Assumptions'!$F$8)*(I4-1)/9 | J11: ='03 Assumptions'!$F$8+('03 Assumptions'!$F$9-'03 Assumptions'!$F$8)*(J4-1)/9 | K11: ='03 Assumptions'!$F$8+('03 Assumptions'!$F$9-'03 Assumptions'!$F$8)*(K4-1)/9 | L11: ='03 Assumptions'!$F$8+('03 Assumptions'!$F$9-'03 Assumptions'!$F$8)*(L4-1)/9 | M11: ='03 Assumptions'!$F$8+('03 Assumptions'!$F$9-'03 Assumptions'!$F$8)*(M4-1)/9 | ... O11: ='03 Assumptions'!$F$8+('03 Assumptions'!$F$9-'03 Assumptions'!$F$8)*(O4-1)/9
A12: Revenue | E12: ='03 Assumptions'!$B$35 | F12: =E12*(1+F11) | G12: =F12*(1+G11) | H12: =G12*(1+H11) | I12: =H12*(1+I11) | J12: =I12*(1+J11) | K12: =J12*(1+K11) | L12: =K12*(1+L11) | M12: =L12*(1+M11) | ... O12: =N12*(1+O11)
A14: DIGITAL ESTIMATION BLOCK (L confidence — every input editable on 03)
A15: B2B installed sites (#) | E15: ='03 Assumptions'!$B$26 | F15: =E15*(1+'03 Assumptions'!$B$27) | G15: =F15*(1+'03 Assumptions'!$B$27) | H15: =G15*(1+'03 Assumptions'!$B$27) | I15: =H15*(1+'03 Assumptions'!$B$27) | J15: =I15*(1+'03 Assumptions'!$B$27) | K15: =J15*(1+'03 Assumptions'!$B$27) | L15: =K15*(1+'03 Assumptions'!$B$27) | M15: =L15*(1+'03 Assumptions'!$B$27) | ... O15: =N15*(1+'03 Assumptions'!$B$27)
A16: B2B attach rate (ramp to endpoint by 2030) | E16: ='03 Assumptions'!$B$32 | F16: ='03 Assumptions'!$B$32+('03 Assumptions'!$F$10-'03 Assumptions'!$B$32)*MIN(F4,5)/5 | G16: ='03 Assumptions'!$B$32+('03 Assumptions'!$F$10-'03 Assumptions'!$B$32)*MIN(G4,5)/5 | H16: ='03 Assumptions'!$B$32+('03 Assumptions'!$F$10-'03 Assumptions'!$B$32)*MIN(H4,5)/5 | I16: ='03 Assumptions'!$B$32+('03 Assumptions'!$F$10-'03 Assumptions'!$B$32)*MIN(I4,5)/5 | J16: ='03 Assumptions'!$B$32+('03 Assumptions'!$F$10-'03 Assumptions'!$B$32)*MIN(J4,5)/5 | K16: ='03 Assumptions'!$B$32+('03 Assumptions'!$F$10-'03 Assumptions'!$B$32)*MIN(K4,5)/5 | L16: ='03 Assumptions'!$B$32+('03 Assumptions'!$F$10-'03 Assumptions'!$B$32)*MIN(L4,5)/5 | M16: ='03 Assumptions'!$B$32+('03 Assumptions'!$F$10-'03 Assumptions'!$B$32)*MIN(M4,5)/5 | ... O16: ='03 Assumptions'!$B$32+('03 Assumptions'!$F$10-'03 Assumptions'!$B$32)*MIN(O4,5)/5
A17: B2B ARPU (€/site/yr) | E17: ='03 Assumptions'!$B$28 | F17: =E17*(1+'03 Assumptions'!$F$12) | G17: =F17*(1+'03 Assumptions'!$F$12) | H17: =G17*(1+'03 Assumptions'!$F$12) | I17: =H17*(1+'03 Assumptions'!$F$12) | J17: =I17*(1+'03 Assumptions'!$F$12) | K17: =J17*(1+'03 Assumptions'!$F$12) | L17: =K17*(1+'03 Assumptions'!$F$12) | M17: =L17*(1+'03 Assumptions'!$F$12) | ... O17: =N17*(1+'03 Assumptions'!$F$12)
A18: B2B digital revenue (€m) | E18: =E15*E16*E17/1000000 | F18: =F15*F16*F17/1000000 | G18: =G15*G16*G17/1000000 | H18: =H15*H16*H17/1000000 | I18: =I15*I16*I17/1000000 | J18: =J15*J16*J17/1000000 | K18: =K15*K16*K17/1000000 | L18: =L15*L16*L17/1000000 | ... O18: =O15*O16*O17/1000000
A20: Consumer connected homes (#) | E20: ='03 Assumptions'!$B$29 | F20: =E20*(1+'03 Assumptions'!$B$30) | G20: =F20*(1+'03 Assumptions'!$B$30) | H20: =G20*(1+'03 Assumptions'!$B$30) | I20: =H20*(1+'03 Assumptions'!$B$30) | J20: =I20*(1+'03 Assumptions'!$B$30) | K20: =J20*(1+'03 Assumptions'!$B$30) | L20: =K20*(1+'03 Assumptions'!$B$30) | M20: =L20*(1+'03 Assumptions'!$B$30) | ... O20: =N20*(1+'03 Assumptions'!$B$30)
A21: Consumer attach rate | E21: ='03 Assumptions'!$B$33 | F21: ='03 Assumptions'!$B$33+('03 Assumptions'!$F$11-'03 Assumptions'!$B$33)*MIN(F4,5)/5 | G21: ='03 Assumptions'!$B$33+('03 Assumptions'!$F$11-'03 Assumptions'!$B$33)*MIN(G4,5)/5 | H21: ='03 Assumptions'!$B$33+('03 Assumptions'!$F$11-'03 Assumptions'!$B$33)*MIN(H4,5)/5 | I21: ='03 Assumptions'!$B$33+('03 Assumptions'!$F$11-'03 Assumptions'!$B$33)*MIN(I4,5)/5 | J21: ='03 Assumptions'!$B$33+('03 Assumptions'!$F$11-'03 Assumptions'!$B$33)*MIN(J4,5)/5 | K21: ='03 Assumptions'!$B$33+('03 Assumptions'!$F$11-'03 Assumptions'!$B$33)*MIN(K4,5)/5 | L21: ='03 Assumptions'!$B$33+('03 Assumptions'!$F$11-'03 Assumptions'!$B$33)*MIN(L4,5)/5 | M21: ='03 Assumptions'!$B$33+('03 Assumptions'!$F$11-'03 Assumptions'!$B$33)*MIN(M4,5)/5 | ... O21: ='03 Assumptions'!$B$33+('03 Assumptions'!$F$11-'03 Assumptions'!$B$33)*MIN(O4,5)/5
A22: Consumer ARPU (€/user/yr) | E22: ='03 Assumptions'!$B$31 | F22: =E22*(1+'03 Assumptions'!$F$12) | G22: =F22*(1+'03 Assumptions'!$F$12) | H22: =G22*(1+'03 Assumptions'!$F$12) | I22: =H22*(1+'03 Assumptions'!$F$12) | J22: =I22*(1+'03 Assumptions'!$F$12) | K22: =J22*(1+'03 Assumptions'!$F$12) | L22: =K22*(1+'03 Assumptions'!$F$12) | M22: =L22*(1+'03 Assumptions'!$F$12) | ... O22: =N22*(1+'03 Assumptions'!$F$12)
A23: Consumer digital revenue (€m) | E23: =E20*E21*E22/1000000 | F23: =F20*F21*F22/1000000 | G23: =G20*G21*G22/1000000 | H23: =H20*H21*H22/1000000 | I23: =I20*I21*I22/1000000 | J23: =J20*J21*J22/1000000 | K23: =K20*K21*K22/1000000 | L23: =L20*L21*L22/1000000 | ... O23: =O20*O21*O22/1000000
A25: Total digital revenue | E25: =E18+E23 | F25: =F18+F23 | G25: =G18+G23 | H25: =H18+H23 | I25: =I18+I23 | J25: =J18+J23 | K25: =K18+K23 | L25: =L18+L23 | ... O25: =O18+O23
A27: TOTAL REVENUE | E27: =E8+E12+E25 | F27: =F8+F12+F25 | G27: =G8+G12+G25 | H27: =H8+H12+H25 | I27: =I8+I12+I25 | J27: =J8+J12+J25 | K27: =K8+K12+K25 | L27: =L8+L12+L25 | ... O27: =O8+O12+O25
A28: Total growth | F28: =F27/E27-1 | G28: =G27/F27-1 | H28: =H27/G27-1 | I28: =I27/H27-1 | J28: =J27/I27-1 | K28: =K27/J27-1 | L28: =L27/K27-1 | M28: =M27/L27-1 | ... O28: =O27/N27-1
A29: Digital % of revenue | E29: =E25/E27 | F29: =F25/F27 | G29: =G25/G27 | H29: =H25/H27 | I29: =I25/I27 | J29: =J25/J27 | K29: =K25/K27 | L29: =L25/L27 | ... O29: =O25/O27
A31: =IF(ABS(E27-1019.3)<1,"CHECK OK: 2025 build ties to reported revenue","ERROR: 2025 revenue build broken")
A32: BEAR BtoB growth path (explicit cyclical: 2027 downturn −10%, recovery from 2029) | F32: 0.04 | G32: -0.1 | H32: -0.03 | I32: 0.06 | J32: 0.05 | K32: 0.045 | L32: 0.04 | M32: 0.035 | N32: 0.03 | O32: 0.025
A33: BEAR EBITDA margin path (2027 trough 19.0%, recovers to 21.5%) | F33: 0.205 | G33: 0.19 | H33: 0.198 | I33: 0.205 | J33: 0.208 | K33: 0.21 | L33: 0.212 | M33: 0.213 | N33: 0.214 | O33: 0.215

Sheet 06 Operating Model
A1: OPERATING MODEL
A3: €m unless noted | F3: 2026E | G3: 2027E | H3: 2028E | I3: 2029E | J3: 2030E | K3: 2031E | L3: 2032E | M3: 2033E | N3: 2034E | O3: 2035E
A4: Revenue | F4: ='05 Revenue Build'!F27 | G4: ='05 Revenue Build'!G27 | H4: ='05 Revenue Build'!H27 | I4: ='05 Revenue Build'!I27 | J4: ='05 Revenue Build'!J27 | K4: ='05 Revenue Build'!K27 | L4: ='05 Revenue Build'!L27 | M4: ='05 Revenue Build'!M27 | ... O4: ='05 Revenue Build'!O27
A5: Total EBITDA margin (OUTPUT = hardware + digital blocks, rows 20-26) | F5: =F6/F4 | G5: =G6/G4 | H5: =H6/H4 | I5: =I6/I4 | J5: =J6/J4 | K5: =K6/K4 | L5: =L6/L4 | M5: =M6/M4 | ... O5: =O6/O4
A6: EBITDA | F6: =IF('03 Assumptions'!$B$3=1,F4*'05 Revenue Build'!F33,F26) | G6: =IF('03 Assumptions'!$B$3=1,G4*'05 Revenue Build'!G33,G26) | H6: =IF('03 Assumptions'!$B$3=1,H4*'05 Revenue Build'!H33,H26) | I6: =IF('03 Assumptions'!$B$3=1,I4*'05 Revenue Build'!I33,I26) | J6: =IF('03 Assumptions'!$B$3=1,J4*'05 Revenue Build'!J33,J26) | K6: =IF('03 Assumptions'!$B$3=1,K4*'05 Revenue Build'!K33,K26) | L6: =IF('03 Assumptions'!$B$3=1,L4*'05 Revenue Build'!L33,L26) | M6: =IF('03 Assumptions'!$B$3=1,M4*'05 Revenue Build'!M33,M26) | ... O6: =IF('03 Assumptions'!$B$3=1,O4*'05 Revenue Build'!O33,O26)
A7: D&A (% revenue) | F7: =-F4*'03 Assumptions'!$B$22 | G7: =-G4*'03 Assumptions'!$B$22 | H7: =-H4*'03 Assumptions'!$B$22 | I7: =-I4*'03 Assumptions'!$B$22 | J7: =-J4*'03 Assumptions'!$B$22 | K7: =-K4*'03 Assumptions'!$B$22 | L7: =-L4*'03 Assumptions'!$B$22 | M7: =-M4*'03 Assumptions'!$B$22 | ... O7: =-O4*'03 Assumptions'!$B$22
A8: EBIT | F8: =F6+F7 | G8: =G6+G7 | H8: =H6+H7 | I8: =I6+I7 | J8: =J6+J7 | K8: =K6+K7 | L8: =L6+L7 | M8: =M6+M7 | ... O8: =O6+O7
A9: Tax on EBIT | F9: =-F8*'03 Assumptions'!$B$21 | G9: =-G8*'03 Assumptions'!$B$21 | H9: =-H8*'03 Assumptions'!$B$21 | I9: =-I8*'03 Assumptions'!$B$21 | J9: =-J8*'03 Assumptions'!$B$21 | K9: =-K8*'03 Assumptions'!$B$21 | L9: =-L8*'03 Assumptions'!$B$21 | M9: =-M8*'03 Assumptions'!$B$21 | ... O9: =-O8*'03 Assumptions'!$B$21
A10: NOPAT | F10: =F8+F9 | G10: =G8+G9 | H10: =H8+H9 | I10: =I8+I9 | J10: =J8+J9 | K10: =K8+K9 | L10: =L8+L9 | M10: =M8+M9 | ... O10: =O8+O9
A12: EBIT margin | F12: =F8/F4 | G12: =G8/G4 | H12: =H8/H4 | I12: =I8/I4 | J12: =J8/J4 | K12: =K8/K4 | L12: =L8/L4 | M12: =M8/M4 | ... O12: =O8/O4
A13: =IF(AND(F5>0.1,O5<0.35),"CHECK OK: margins in sane range","CHECK: margin path out of range")
A15: Note: SBC immaterial (<0.35% dilution) — not modeled. Non-recurring items excluded (adjusted basis).
A17: Margin note: 17.5% (2021) -> 21.6% (2025) benefited from post-COVID pent-up demand, supply-chain normalisation and one-time procurement gains. Sustaining a 23.5% TOTAL by 2032 needs the digital/services mix shift + operating leverage, not more procurement.
A19: DIGITAL-ISOLATED EBITDA BUILD (v3) — base/bull isolate; bear uses explicit cyclical total-margin path (05!row33)
A20: Hardware revenue (ex-digital) | F20: ='05 Revenue Build'!F8+'05 Revenue Build'!F12 | G20: ='05 Revenue Build'!G8+'05 Revenue Build'!G12 | H20: ='05 Revenue Build'!H8+'05 Revenue Build'!H12 | I20: ='05 Revenue Build'!I8+'05 Revenue Build'!I12 | J20: ='05 Revenue Build'!J8+'05 Revenue Build'!J12 | K20: ='05 Revenue Build'!K8+'05 Revenue Build'!K12 | L20: ='05 Revenue Build'!L8+'05 Revenue Build'!L12 | M20: ='05 Revenue Build'!M8+'05 Revenue Build'!M12 | ... O20: ='05 Revenue Build'!O8+'05 Revenue Build'!O12
A21: Digital revenue | F21: ='05 Revenue Build'!F25 | G21: ='05 Revenue Build'!G25 | H21: ='05 Revenue Build'!H25 | I21: ='05 Revenue Build'!I25 | J21: ='05 Revenue Build'!J25 | K21: ='05 Revenue Build'!K25 | L21: ='05 Revenue Build'!L25 | M21: ='05 Revenue Build'!M25 | ... O21: ='05 Revenue Build'!O25
A22: Hardware 2025 EBITDA margin (derived to tie reported EUR 220.1m) | B22: =(220.1-'03 Assumptions'!B36*'03 Assumptions'!F18)/('03 Assumptions'!B34+'03 Assumptions'!B35)
A23: Hardware EBITDA margin (path B22 -> 03!F13 endpoint by 2032) | F23: =$B$22+('03 Assumptions'!$F$13-$B$22)*MIN('05 Revenue Build'!F$4,7)/7 | G23: =$B$22+('03 Assumptions'!$F$13-$B$22)*MIN('05 Revenue Build'!G$4,7)/7 | H23: =$B$22+('03 Assumptions'!$F$13-$B$22)*MIN('05 Revenue Build'!H$4,7)/7 | I23: =$B$22+('03 Assumptions'!$F$13-$B$22)*MIN('05 Revenue Build'!I$4,7)/7 | J23: =$B$22+('03 Assumptions'!$F$13-$B$22)*MIN('05 Revenue Build'!J$4,7)/7 | K23: =$B$22+('03 Assumptions'!$F$13-$B$22)*MIN('05 Revenue Build'!K$4,7)/7 | L23: =$B$22+('03 Assumptions'!$F$13-$B$22)*MIN('05 Revenue Build'!L$4,7)/7 | M23: =$B$22+('03 Assumptions'!$F$13-$B$22)*MIN('05 Revenue Build'!M$4,7)/7 | ... O23: =$B$22+('03 Assumptions'!$F$13-$B$22)*MIN('05 Revenue Build'!O$4,7)/7
A24: Hardware EBITDA | F24: =F20*F23 | G24: =G20*G23 | H24: =H20*H23 | I24: =I20*I23 | J24: =J20*J23 | K24: =K20*K23 | L24: =L20*L23 | M24: =M20*M23 | ... O24: =O20*O23
A25: Digital EBITDA (margin = 03!F18) | F25: =F21*'03 Assumptions'!$F$18 | G25: =G21*'03 Assumptions'!$F$18 | H25: =H21*'03 Assumptions'!$F$18 | I25: =I21*'03 Assumptions'!$F$18 | J25: =J21*'03 Assumptions'!$F$18 | K25: =K21*'03 Assumptions'!$F$18 | L25: =L21*'03 Assumptions'!$F$18 | M25: =M21*'03 Assumptions'!$F$18 | ... O25: =O21*'03 Assumptions'!$F$18
A26: TOTAL EBITDA (hardware + digital) [feeds row 6 in base/bull] | F26: =F24+F25 | G26: =G24+G25 | H26: =H24+H25 | I26: =I24+I25 | J26: =J24+J25 | K26: =K24+K25 | L26: =L24+L25 | M26: =M24+M25 | ... O26: =O24+O25

Sheet 07 Working Capital
A1: WORKING CAPITAL
A3: €m unless noted | F3: 2026E | G3: 2027E | H3: 2028E | I3: 2029E | J3: 2030E | K3: 2031E | L3: 2032E | M3: 2033E | N3: 2034E | O3: 2035E
A4: Revenue | F4: ='05 Revenue Build'!F27 | G4: ='05 Revenue Build'!G27 | H4: ='05 Revenue Build'!H27 | I4: ='05 Revenue Build'!I27 | J4: ='05 Revenue Build'!J27 | K4: ='05 Revenue Build'!K27 | L4: ='05 Revenue Build'!L27 | M4: ='05 Revenue Build'!M27 | ... O4: ='05 Revenue Build'!O27
A5: DSO (days, incl. scenario stress) | F5: ='03 Assumptions'!$B$45+'03 Assumptions'!$F$15 | G5: ='03 Assumptions'!$B$45+'03 Assumptions'!$F$15 | H5: ='03 Assumptions'!$B$45+'03 Assumptions'!$F$15 | I5: ='03 Assumptions'!$B$45+'03 Assumptions'!$F$15 | J5: ='03 Assumptions'!$B$45+'03 Assumptions'!$F$15 | K5: ='03 Assumptions'!$B$45+'03 Assumptions'!$F$15 | L5: ='03 Assumptions'!$B$45+'03 Assumptions'!$F$15 | M5: ='03 Assumptions'!$B$45+'03 Assumptions'!$F$15 | ... O5: ='03 Assumptions'!$B$45+'03 Assumptions'!$F$15
A6: DIO (days on materials) | F6: ='03 Assumptions'!$B$46 | G6: ='03 Assumptions'!$B$46 | H6: ='03 Assumptions'!$B$46 | I6: ='03 Assumptions'!$B$46 | J6: ='03 Assumptions'!$B$46 | K6: ='03 Assumptions'!$B$46 | L6: ='03 Assumptions'!$B$46 | M6: ='03 Assumptions'!$B$46 | ... O6: ='03 Assumptions'!$B$46
A7: DPO (days on materials; bear compresses) | F7: ='03 Assumptions'!$B$47-IF('03 Assumptions'!$B$3=1,'03 Assumptions'!$B$49,0) | G7: ='03 Assumptions'!$B$47-IF('03 Assumptions'!$B$3=1,'03 Assumptions'!$B$49,0) | H7: ='03 Assumptions'!$B$47-IF('03 Assumptions'!$B$3=1,'03 Assumptions'!$B$49,0) | I7: ='03 Assumptions'!$B$47-IF('03 Assumptions'!$B$3=1,'03 Assumptions'!$B$49,0) | J7: ='03 Assumptions'!$B$47-IF('03 Assumptions'!$B$3=1,'03 Assumptions'!$B$49,0) | K7: ='03 Assumptions'!$B$47-IF('03 Assumptions'!$B$3=1,'03 Assumptions'!$B$49,0) | L7: ='03 Assumptions'!$B$47-IF('03 Assumptions'!$B$3=1,'03 Assumptions'!$B$49,0) | M7: ='03 Assumptions'!$B$47-IF('03 Assumptions'!$B$3=1,'03 Assumptions'!$B$49,0) | ... O7: ='03 Assumptions'!$B$47-IF('03 Assumptions'!$B$3=1,'03 Assumptions'!$B$49,0)
A8: Net working capital = Rev x DSO/365 + Mat x (DIO-DPO)/365 | F8: =F4*(F5/365+'03 Assumptions'!$B$48*(F6-F7)/365) | G8: =G4*(G5/365+'03 Assumptions'!$B$48*(G6-G7)/365) | H8: =H4*(H5/365+'03 Assumptions'!$B$48*(H6-H7)/365) | I8: =I4*(I5/365+'03 Assumptions'!$B$48*(I6-I7)/365) | J8: =J4*(J5/365+'03 Assumptions'!$B$48*(J6-J7)/365) | K8: =K4*(K5/365+'03 Assumptions'!$B$48*(K6-K7)/365) | L8: =L4*(L5/365+'03 Assumptions'!$B$48*(L6-L7)/365) | M8: =M4*(M5/365+'03 Assumptions'!$B$48*(M6-M7)/365) | ... O8: =O4*(O5/365+'03 Assumptions'!$B$48*(O6-O7)/365)
A9: Change in NWC (- = cash out) | F9: =-(F8-(1019.3*(F5/365+'03 Assumptions'!$B$48*(F6-'03 Assumptions'!$B$47)/365))) | G9: =-(G8-F8) | H9: =-(H8-G8) | I9: =-(I8-H8) | J9: =-(J8-I8) | K9: =-(K8-J8) | L9: =-(L8-K8) | M9: =-(M8-L8) | N9: =-(N8-M8) | O9: =-(O8-N8)
A12: Effective NWC % of revenue (helper for grids) | B12: =F8/F4
A13: 2025 actual days: DSO 47.3 / DIO 127 / DPO 221 (ties to ~49m NWC = 4.9% rev). Bear stress: DSO +10d, DPO -30d
A14: (gym customers slow-pay; supplier terms tighten in downturns). 2026 change computed vs unstressed-DPO 2025 base.

Sheet 08 Capex & Depreciation
A1: CAPEX & DEPRECIATION
A3: €m unless noted | F3: 2026E | G3: 2027E | H3: 2028E | I3: 2029E | J3: 2030E | K3: 2031E | L3: 2032E | M3: 2033E | N3: 2034E | O3: 2035E
A4: Revenue | F4: ='05 Revenue Build'!F27 | G4: ='05 Revenue Build'!G27 | H4: ='05 Revenue Build'!H27 | I4: ='05 Revenue Build'!I27 | J4: ='05 Revenue Build'!J27 | K4: ='05 Revenue Build'!K27 | L4: ='05 Revenue Build'!L27 | M4: ='05 Revenue Build'!M27 | ... O4: ='05 Revenue Build'!O27
A5: Capex % revenue (scenario) | F5: ='03 Assumptions'!$F$14 | G5: ='03 Assumptions'!$F$14 | H5: ='03 Assumptions'!$F$14 | I5: ='03 Assumptions'!$F$14 | J5: ='03 Assumptions'!$F$14 | K5: ='03 Assumptions'!$F$14 | L5: ='03 Assumptions'!$F$14 | M5: ='03 Assumptions'!$F$14 | ... O5: ='03 Assumptions'!$F$14
A6: Capex | F6: =-F4*F5 | G6: =-G4*G5 | H6: =-H4*H5 | I6: =-I4*I5 | J6: =-J4*J5 | K6: =-K4*K5 | L6: =-L4*L5 | M6: =-M4*M5 | ... O6: =-O4*O5
A7: D&A (from 06) | F7: ='06 Operating Model'!F7 | G7: ='06 Operating Model'!G7 | H7: ='06 Operating Model'!H7 | I7: ='06 Operating Model'!I7 | J7: ='06 Operating Model'!J7 | K7: ='06 Operating Model'!K7 | L7: ='06 Operating Model'!L7 | M7: ='06 Operating Model'!M7 | ... O7: ='06 Operating Model'!O7
A8: Capex / D&A cover | F8: =F6/F7 | G8: =G6/G7 | H8: =H6/H7 | I8: =I6/I7 | J8: =J6/J7 | K8: =K6/K7 | L8: =L6/L7 | M8: =M6/M7 | ... O8: =O6/O7
A10: 2025 actual: recurring capex 5.1% of revenue (gross 6.5% incl. one-off solar/projects). Base 5.0%.

Sheet 09 Free Cash Flow
A1: FREE CASH FLOW TO FIRM
A3: €m unless noted | F3: 2026E | G3: 2027E | H3: 2028E | I3: 2029E | J3: 2030E | K3: 2031E | L3: 2032E | M3: 2033E | N3: 2034E | O3: 2035E
A4: NOPAT | F4: ='06 Operating Model'!F10 | G4: ='06 Operating Model'!G10 | H4: ='06 Operating Model'!H10 | I4: ='06 Operating Model'!I10 | J4: ='06 Operating Model'!J10 | K4: ='06 Operating Model'!K10 | L4: ='06 Operating Model'!L10 | M4: ='06 Operating Model'!M10 | ... O4: ='06 Operating Model'!O10
A5: (+) D&A | F5: =-'06 Operating Model'!F7 | G5: =-'06 Operating Model'!G7 | H5: =-'06 Operating Model'!H7 | I5: =-'06 Operating Model'!I7 | J5: =-'06 Operating Model'!J7 | K5: =-'06 Operating Model'!K7 | L5: =-'06 Operating Model'!L7 | M5: =-'06 Operating Model'!M7 | ... O5: =-'06 Operating Model'!O7
A6: (-) Capex | F6: ='08 Capex & Depreciation'!F6 | G6: ='08 Capex & Depreciation'!G6 | H6: ='08 Capex & Depreciation'!H6 | I6: ='08 Capex & Depreciation'!I6 | J6: ='08 Capex & Depreciation'!J6 | K6: ='08 Capex & Depreciation'!K6 | L6: ='08 Capex & Depreciation'!L6 | M6: ='08 Capex & Depreciation'!M6 | ... O6: ='08 Capex & Depreciation'!O6
A7: (-/+) Change in NWC | F7: ='07 Working Capital'!F9 | G7: ='07 Working Capital'!G9 | H7: ='07 Working Capital'!H9 | I7: ='07 Working Capital'!I9 | J7: ='07 Working Capital'!J9 | K7: ='07 Working Capital'!K9 | L7: ='07 Working Capital'!L9 | M7: ='07 Working Capital'!M9 | ... O7: ='07 Working Capital'!O9
A8: (-) Lease principal repayments (IFRS 16) | F8: =-'05 Revenue Build'!F27*'03 Assumptions'!$B$43 | G8: =-'05 Revenue Build'!G27*'03 Assumptions'!$B$43 | H8: =-'05 Revenue Build'!H27*'03 Assumptions'!$B$43 | I8: =-'05 Revenue Build'!I27*'03 Assumptions'!$B$43 | J8: =-'05 Revenue Build'!J27*'03 Assumptions'!$B$43 | K8: =-'05 Revenue Build'!K27*'03 Assumptions'!$B$43 | L8: =-'05 Revenue Build'!L27*'03 Assumptions'!$B$43 | M8: =-'05 Revenue Build'!M27*'03 Assumptions'!$B$43 | ... O8: =-'05 Revenue Build'!O27*'03 Assumptions'!$B$43
A9: FCFF | F9: =SUM(F4:F8) | G9: =SUM(G4:G8) | H9: =SUM(H4:H8) | I9: =SUM(I4:I8) | J9: =SUM(J4:J8) | K9: =SUM(K4:K8) | L9: =SUM(L4:L8) | M9: =SUM(M4:M8) | ... O9: =SUM(O4:O8)
A10: FCFF / EBITDA conversion | F10: =F9/'06 Operating Model'!F6 | G10: =G9/'06 Operating Model'!G6 | H10: =H9/'06 Operating Model'!H6 | I10: =I9/'06 Operating Model'!I6 | J10: =J9/'06 Operating Model'!J6 | K10: =K9/'06 Operating Model'!K6 | L10: =L9/'06 Operating Model'!L6 | M10: =M9/'06 Operating Model'!M6 | ... O10: =O9/'06 Operating Model'!O6
A12: IFRS 16 v2: EBITDA keeps lease benefit; FCFF charges lease PRINCIPAL (2025: 15.1m, scaled with revenue);
A13: equity bridge uses NFP EXCLUDING lease liabilities (+209.6m). Lease interest ~immaterial (net fin result ~0).

Sheet 10 WACC
A1: WACC BUILD
A3: Risk-free: German Bund 10Y | B3: 0.0313 | D3: TradingEconomics 16-Jul-26
A4: Mature market ERP (Damodaran Jan-26) | B4: 0.0423 | D4: Damodaran ctryprem
A5: Levered beta (triangulated) | B5: 0.95 | D5: Yahoo 0.86 / TradingView 0.94
A6: Weighted country risk premium | B6: 0.006 | D6: Italy CRP 2.46% x ~11% rev + EM exposure
A8: Cost of equity = rf + beta x ERP + wCRP | B8: =B3+B5*B4+B6
A10: Pre-tax cost of debt (hypothetical; net-cash co.) | B10: 0.045
A11: Tax rate | B11: ='03 Assumptions'!$B$21
A12: After-tax cost of debt | B12: =B10*(1-B11)
A13: Weight of debt (net cash → 0%; leases immaterial to weighting) | B13: 0
A15: WACC | B15: =B8*(1-B13)+B12*B13
A17: =IF(AND(B15>0.06,B15<0.10),"CHECK OK: WACC in 6-10% range","CHECK: WACC outside expected range")

Sheet 11 DCF Valuation
A1: DCF VALUATION
A3: €m unless noted | F3: 2026E | G3: 2027E | H3: 2028E | I3: 2029E | J3: 2030E | K3: 2031E | L3: 2032E | M3: 2033E | N3: 2034E | O3: 2035E
A4: FCFF | F4: ='09 Free Cash Flow'!F9 | G4: ='09 Free Cash Flow'!G9 | H4: ='09 Free Cash Flow'!H9 | I4: ='09 Free Cash Flow'!I9 | J4: ='09 Free Cash Flow'!J9 | K4: ='09 Free Cash Flow'!K9 | L4: ='09 Free Cash Flow'!L9 | M4: ='09 Free Cash Flow'!M9 | ... O4: ='09 Free Cash Flow'!O9
A5: Discount factor (year-end) | F5: =1/(1+'10 WACC'!$B$15)^1 | G5: =1/(1+'10 WACC'!$B$15)^2 | H5: =1/(1+'10 WACC'!$B$15)^3 | I5: =1/(1+'10 WACC'!$B$15)^4 | J5: =1/(1+'10 WACC'!$B$15)^5 | K5: =1/(1+'10 WACC'!$B$15)^6 | L5: =1/(1+'10 WACC'!$B$15)^7 | M5: =1/(1+'10 WACC'!$B$15)^8 | N5: =1/(1+'10 WACC'!$B$15)^9 | O5: =1/(1+'10 WACC'!$B$15)^10
A6: PV of FCFF | F6: =F4*F5 | G6: =G4*G5 | H6: =H4*H5 | I6: =I4*I5 | J6: =J4*J5 | K6: =K4*K5 | L6: =L4*L5 | M6: =M4*M5 | ... O6: =O4*O5
A8: Sum PV explicit FCFF (2026-35) | B8: =SUM(F6:O6)
A10: TERMINAL VALUE — Method 1: Gordon Growth
A11: Terminal growth g (scenario) | B11: ='03 Assumptions'!$F$16
A12: TV = FCFF2035 x (1+g) / (WACC − g) | B12: =O4*(1+B11)/('10 WACC'!$B$15-B11)
A13: PV of TV | B13: =B12*O5
A14: Implied exit EV/EBITDA (check vs Method 2) | B14: =B12/'06 Operating Model'!O6
A16: TERMINAL VALUE — Method 2: Exit multiple
A17: Exit multiple (scenario) | B17: ='03 Assumptions'!$F$17
A18: TV = 2035 EBITDA x multiple | B18: ='06 Operating Model'!O6*B17
A19: PV of TV | B19: =B18*O5
A20: Implied terminal growth (check) | B20: =('10 WACC'!$B$15*B18-O4)/(B18+O4)
A22: ENTERPRISE → EQUITY (Gordon primary)
A23: Enterprise value | B23: =B8+B13
A24: (+) NFP excl. IFRS16 (leases charged in FCFF) | B24: ='03 Assumptions'!$B$44
A25: Equity value | B25: =B23+B24
A26: Shares (m) | B26: ='03 Assumptions'!$B$23
A27: VALUE PER SHARE (€) | B27: =B25/B26
A28: Current price (€) | B28: ='03 Assumptions'!$B$25
A29: Upside / (downside) | B29: =B27/B28-1
A31: Per share — exit-multiple method | B31: =(B8+B19+B24)/B26
A32: TV % of EV (Gordon) | B32: =B13/B23
A34: =IF('10 WACC'!$B$15>B11,"CHECK OK: WACC > g","ERROR: WACC <= g - Gordon invalid")
A35: =IF(ABS(B27-B31)/B27<0.35,"CHECK OK: two TV methods within 35%","CHECK: TV methods diverge >35% - review exit multiple vs g")
A37: 5-YEAR HORIZON CROSS-CHECK (partner request)
A38: EV: PV FCFF 2026-30 + TV (exit mult x 2030 EBITDA) | B38: =SUMPRODUCT(F4:J4,F5:J5)+'06 Operating Model'!J6*'03 Assumptions'!$F$17*J5
A39: 5-yr value per share | B39: =(B38+B24)/B26
A40: TV % of 5-yr EV | B40: ='06 Operating Model'!J6*'03 Assumptions'!$F$17*J5/B38
A42: Gordon-implied exit multiple (B14, currently ~9.4x) is BELOW today's ~13x trading multiple — correctly assuming a mature capital-goods re-rating, not a premium.
A43: The 12.0x exit-multiple cross-check (B17) sits above the Gordon-implied ~9.4x: the gap embeds a premium for unquantified digital optionality. Two methods agree within ~16%.

Sheet 12 Sensitivity Analysis
A1: SENSITIVITY ANALYSIS
A2: Grids re-derive value from the live FCFF row of sheet 11; margin×growth grid uses a simplified engine (uniform growth/margin) noted below.
A4: GRID 1 — WACC (rows) × terminal growth (cols)
C5: 0.015 | D5: 0.02 | E5: 0.0225 | F5: 0.025 | G5: 0.03
B6: 0.07 | C6: =(SUMPRODUCT('11 DCF Valuation'!$F$4:$O$4,1/(1+$B6)^'05 Revenue Build'!$F$4:$O$4)+'11 DCF Valuation'!$O$4*(1+C$5)/($B6-C$5)/(1+$B6)^10+'03 Assumptions'!$B$44)/'03 Assumptions'!$B$23 | D6: =(SUMPRODUCT('11 DCF Valuation'!$F$4:$O$4,1/(1+$B6)^'05 Revenue Build'!$F$4:$O$4)+'11 DCF Valuation'!$O$4*(1+D$5)/($B6-D$5)/(1+$B6)^10+'03 Assumptions'!$B$44)/'03 Assumptions'!$B$23 | E6: =(SUMPRODUCT('11 DCF Valuation'!$F$4:$O$4,1/(1+$B6)^'05 Revenue Build'!$F$4:$O$4)+'11 DCF Valuation'!$O$4*(1+E$5)/($B6-E$5)/(1+$B6)^10+'03 Assumptions'!$B$44)/'03 Assumptions'!$B$23 | F6: =(SUMPRODUCT('11 DCF Valuation'!$F$4:$O$4,1/(1+$B6)^'05 Revenue Build'!$F$4:$O$4)+'11 DCF Valuation'!$O$4*(1+F$5)/($B6-F$5)/(1+$B6)^10+'03 Assumptions'!$B$44)/'03 Assumptions'!$B$23 | G6: =(SUMPRODUCT('11 DCF Valuation'!$F$4:$O$4,1/(1+$B6)^'05 Revenue Build'!$F$4:$O$4)+'11 DCF Valuation'!$O$4*(1+G$5)/($B6-G$5)/(1+$B6)^10+'03 Assumptions'!$B$44)/'03 Assumptions'!$B$23
B7: 0.0725 | C7: =(SUMPRODUCT('11 DCF Valuation'!$F$4:$O$4,1/(1+$B7)^'05 Revenue Build'!$F$4:$O$4)+'11 DCF Valuation'!$O$4*(1+C$5)/($B7-C$5)/(1+$B7)^10+'03 Assumptions'!$B$44)/'03 Assumptions'!$B$23 | D7: =(SUMPRODUCT('11 DCF Valuation'!$F$4:$O$4,1/(1+$B7)^'05 Revenue Build'!$F$4:$O$4)+'11 DCF Valuation'!$O$4*(1+D$5)/($B7-D$5)/(1+$B7)^10+'03 Assumptions'!$B$44)/'03 Assumptions'!$B$23 | E7: =(SUMPRODUCT('11 DCF Valuation'!$F$4:$O$4,1/(1+$B7)^'05 Revenue Build'!$F$4:$O$4)+'11 DCF Valuation'!$O$4*(1+E$5)/($B7-E$5)/(1+$B7)^10+'03 Assumptions'!$B$44)/'03 Assumptions'!$B$23 | F7: =(SUMPRODUCT('11 DCF Valuation'!$F$4:$O$4,1/(1+$B7)^'05 Revenue Build'!$F$4:$O$4)+'11 DCF Valuation'!$O$4*(1+F$5)/($B7-F$5)/(1+$B7)^10+'03 Assumptions'!$B$44)/'03 Assumptions'!$B$23 | G7: =(SUMPRODUCT('11 DCF Valuation'!$F$4:$O$4,1/(1+$B7)^'05 Revenue Build'!$F$4:$O$4)+'11 DCF Valuation'!$O$4*(1+G$5)/($B7-G$5)/(1+$B7)^10+'03 Assumptions'!$B$44)/'03 Assumptions'!$B$23
B8: 0.075 | C8: =(SUMPRODUCT('11 DCF Valuation'!$F$4:$O$4,1/(1+$B8)^'05 Revenue Build'!$F$4:$O$4)+'11 DCF Valuation'!$O$4*(1+C$5)/($B8-C$5)/(1+$B8)^10+'03 Assumptions'!$B$44)/'03 Assumptions'!$B$23 | D8: =(SUMPRODUCT('11 DCF Valuation'!$F$4:$O$4,1/(1+$B8)^'05 Revenue Build'!$F$4:$O$4)+'11 DCF Valuation'!$O$4*(1+D$5)/($B8-D$5)/(1+$B8)^10+'03 Assumptions'!$B$44)/'03 Assumptions'!$B$23 | E8: =(SUMPRODUCT('11 DCF Valuation'!$F$4:$O$4,1/(1+$B8)^'05 Revenue Build'!$F$4:$O$4)+'11 DCF Valuation'!$O$4*(1+E$5)/($B8-E$5)/(1+$B8)^10+'03 Assumptions'!$B$44)/'03 Assumptions'!$B$23 | F8: =(SUMPRODUCT('11 DCF Valuation'!$F$4:$O$4,1/(1+$B8)^'05 Revenue Build'!$F$4:$O$4)+'11 DCF Valuation'!$O$4*(1+F$5)/($B8-F$5)/(1+$B8)^10+'03 Assumptions'!$B$44)/'03 Assumptions'!$B$23 | G8: =(SUMPRODUCT('11 DCF Valuation'!$F$4:$O$4,1/(1+$B8)^'05 Revenue Build'!$F$4:$O$4)+'11 DCF Valuation'!$O$4*(1+G$5)/($B8-G$5)/(1+$B8)^10+'03 Assumptions'!$B$44)/'03 Assumptions'!$B$23
B9: 0.0775 | C9: =(SUMPRODUCT('11 DCF Valuation'!$F$4:$O$4,1/(1+$B9)^'05 Revenue Build'!$F$4:$O$4)+'11 DCF Valuation'!$O$4*(1+C$5)/($B9-C$5)/(1+$B9)^10+'03 Assumptions'!$B$44)/'03 Assumptions'!$B$23 | D9: =(SUMPRODUCT('11 DCF Valuation'!$F$4:$O$4,1/(1+$B9)^'05 Revenue Build'!$F$4:$O$4)+'11 DCF Valuation'!$O$4*(1+D$5)/($B9-D$5)/(1+$B9)^10+'03 Assumptions'!$B$44)/'03 Assumptions'!$B$23 | E9: =(SUMPRODUCT('11 DCF Valuation'!$F$4:$O$4,1/(1+$B9)^'05 Revenue Build'!$F$4:$O$4)+'11 DCF Valuation'!$O$4*(1+E$5)/($B9-E$5)/(1+$B9)^10+'03 Assumptions'!$B$44)/'03 Assumptions'!$B$23 | F9: =(SUMPRODUCT('11 DCF Valuation'!$F$4:$O$4,1/(1+$B9)^'05 Revenue Build'!$F$4:$O$4)+'11 DCF Valuation'!$O$4*(1+F$5)/($B9-F$5)/(1+$B9)^10+'03 Assumptions'!$B$44)/'03 Assumptions'!$B$23 | G9: =(SUMPRODUCT('11 DCF Valuation'!$F$4:$O$4,1/(1+$B9)^'05 Revenue Build'!$F$4:$O$4)+'11 DCF Valuation'!$O$4*(1+G$5)/($B9-G$5)/(1+$B9)^10+'03 Assumptions'!$B$44)/'03 Assumptions'!$B$23
B10: 0.08 | C10: =(SUMPRODUCT('11 DCF Valuation'!$F$4:$O$4,1/(1+$B10)^'05 Revenue Build'!$F$4:$O$4)+'11 DCF Valuation'!$O$4*(1+C$5)/($B10-C$5)/(1+$B10)^10+'03 Assumptions'!$B$44)/'03 Assumptions'!$B$23 | D10: =(SUMPRODUCT('11 DCF Valuation'!$F$4:$O$4,1/(1+$B10)^'05 Revenue Build'!$F$4:$O$4)+'11 DCF Valuation'!$O$4*(1+D$5)/($B10-D$5)/(1+$B10)^10+'03 Assumptions'!$B$44)/'03 Assumptions'!$B$23 | E10: =(SUMPRODUCT('11 DCF Valuation'!$F$4:$O$4,1/(1+$B10)^'05 Revenue Build'!$F$4:$O$4)+'11 DCF Valuation'!$O$4*(1+E$5)/($B10-E$5)/(1+$B10)^10+'03 Assumptions'!$B$44)/'03 Assumptions'!$B$23 | F10: =(SUMPRODUCT('11 DCF Valuation'!$F$4:$O$4,1/(1+$B10)^'05 Revenue Build'!$F$4:$O$4)+'11 DCF Valuation'!$O$4*(1+F$5)/($B10-F$5)/(1+$B10)^10+'03 Assumptions'!$B$44)/'03 Assumptions'!$B$23 | G10: =(SUMPRODUCT('11 DCF Valuation'!$F$4:$O$4,1/(1+$B10)^'05 Revenue Build'!$F$4:$O$4)+'11 DCF Valuation'!$O$4*(1+G$5)/($B10-G$5)/(1+$B10)^10+'03 Assumptions'!$B$44)/'03 Assumptions'!$B$23
B11: 0.085 | C11: =(SUMPRODUCT('11 DCF Valuation'!$F$4:$O$4,1/(1+$B11)^'05 Revenue Build'!$F$4:$O$4)+'11 DCF Valuation'!$O$4*(1+C$5)/($B11-C$5)/(1+$B11)^10+'03 Assumptions'!$B$44)/'03 Assumptions'!$B$23 | D11: =(SUMPRODUCT('11 DCF Valuation'!$F$4:$O$4,1/(1+$B11)^'05 Revenue Build'!$F$4:$O$4)+'11 DCF Valuation'!$O$4*(1+D$5)/($B11-D$5)/(1+$B11)^10+'03 Assumptions'!$B$44)/'03 Assumptions'!$B$23 | E11: =(SUMPRODUCT('11 DCF Valuation'!$F$4:$O$4,1/(1+$B11)^'05 Revenue Build'!$F$4:$O$4)+'11 DCF Valuation'!$O$4*(1+E$5)/($B11-E$5)/(1+$B11)^10+'03 Assumptions'!$B$44)/'03 Assumptions'!$B$23 | F11: =(SUMPRODUCT('11 DCF Valuation'!$F$4:$O$4,1/(1+$B11)^'05 Revenue Build'!$F$4:$O$4)+'11 DCF Valuation'!$O$4*(1+F$5)/($B11-F$5)/(1+$B11)^10+'03 Assumptions'!$B$44)/'03 Assumptions'!$B$23 | G11: =(SUMPRODUCT('11 DCF Valuation'!$F$4:$O$4,1/(1+$B11)^'05 Revenue Build'!$F$4:$O$4)+'11 DCF Valuation'!$O$4*(1+G$5)/($B11-G$5)/(1+$B11)^10+'03 Assumptions'!$B$44)/'03 Assumptions'!$B$23
A14: GRID 2 — WACC (rows) × exit EV/EBITDA (cols)
C15: 9 | D15: 10 | E15: 11 | F15: 12 | G15: 13 | H15: 14
B16: 0.07 | C16: =(SUMPRODUCT('11 DCF Valuation'!$F$4:$O$4,1/(1+$B16)^'05 Revenue Build'!$F$4:$O$4)+'06 Operating Model'!$O$6*C$15/(1+$B16)^10+'03 Assumptions'!$B$44)/'03 Assumptions'!$B$23 | D16: =(SUMPRODUCT('11 DCF Valuation'!$F$4:$O$4,1/(1+$B16)^'05 Revenue Build'!$F$4:$O$4)+'06 Operating Model'!$O$6*D$15/(1+$B16)^10+'03 Assumptions'!$B$44)/'03 Assumptions'!$B$23 | E16: =(SUMPRODUCT('11 DCF Valuation'!$F$4:$O$4,1/(1+$B16)^'05 Revenue Build'!$F$4:$O$4)+'06 Operating Model'!$O$6*E$15/(1+$B16)^10+'03 Assumptions'!$B$44)/'03 Assumptions'!$B$23 | F16: =(SUMPRODUCT('11 DCF Valuation'!$F$4:$O$4,1/(1+$B16)^'05 Revenue Build'!$F$4:$O$4)+'06 Operating Model'!$O$6*F$15/(1+$B16)^10+'03 Assumptions'!$B$44)/'03 Assumptions'!$B$23 | G16: =(SUMPRODUCT('11 DCF Valuation'!$F$4:$O$4,1/(1+$B16)^'05 Revenue Build'!$F$4:$O$4)+'06 Operating Model'!$O$6*G$15/(1+$B16)^10+'03 Assumptions'!$B$44)/'03 Assumptions'!$B$23 | H16: =(SUMPRODUCT('11 DCF Valuation'!$F$4:$O$4,1/(1+$B16)^'05 Revenue Build'!$F$4:$O$4)+'06 Operating Model'!$O$6*H$15/(1+$B16)^10+'03 Assumptions'!$B$44)/'03 Assumptions'!$B$23
B17: 0.0725 | C17: =(SUMPRODUCT('11 DCF Valuation'!$F$4:$O$4,1/(1+$B17)^'05 Revenue Build'!$F$4:$O$4)+'06 Operating Model'!$O$6*C$15/(1+$B17)^10+'03 Assumptions'!$B$44)/'03 Assumptions'!$B$23 | D17: =(SUMPRODUCT('11 DCF Valuation'!$F$4:$O$4,1/(1+$B17)^'05 Revenue Build'!$F$4:$O$4)+'06 Operating Model'!$O$6*D$15/(1+$B17)^10+'03 Assumptions'!$B$44)/'03 Assumptions'!$B$23 | E17: =(SUMPRODUCT('11 DCF Valuation'!$F$4:$O$4,1/(1+$B17)^'05 Revenue Build'!$F$4:$O$4)+'06 Operating Model'!$O$6*E$15/(1+$B17)^10+'03 Assumptions'!$B$44)/'03 Assumptions'!$B$23 | F17: =(SUMPRODUCT('11 DCF Valuation'!$F$4:$O$4,1/(1+$B17)^'05 Revenue Build'!$F$4:$O$4)+'06 Operating Model'!$O$6*F$15/(1+$B17)^10+'03 Assumptions'!$B$44)/'03 Assumptions'!$B$23 | G17: =(SUMPRODUCT('11 DCF Valuation'!$F$4:$O$4,1/(1+$B17)^'05 Revenue Build'!$F$4:$O$4)+'06 Operating Model'!$O$6*G$15/(1+$B17)^10+'03 Assumptions'!$B$44)/'03 Assumptions'!$B$23 | H17: =(SUMPRODUCT('11 DCF Valuation'!$F$4:$O$4,1/(1+$B17)^'05 Revenue Build'!$F$4:$O$4)+'06 Operating Model'!$O$6*H$15/(1+$B17)^10+'03 Assumptions'!$B$44)/'03 Assumptions'!$B$23
B18: 0.075 | C18: =(SUMPRODUCT('11 DCF Valuation'!$F$4:$O$4,1/(1+$B18)^'05 Revenue Build'!$F$4:$O$4)+'06 Operating Model'!$O$6*C$15/(1+$B18)^10+'03 Assumptions'!$B$44)/'03 Assumptions'!$B$23 | D18: =(SUMPRODUCT('11 DCF Valuation'!$F$4:$O$4,1/(1+$B18)^'05 Revenue Build'!$F$4:$O$4)+'06 Operating Model'!$O$6*D$15/(1+$B18)^10+'03 Assumptions'!$B$44)/'03 Assumptions'!$B$23 | E18: =(SUMPRODUCT('11 DCF Valuation'!$F$4:$O$4,1/(1+$B18)^'05 Revenue Build'!$F$4:$O$4)+'06 Operating Model'!$O$6*E$15/(1+$B18)^10+'03 Assumptions'!$B$44)/'03 Assumptions'!$B$23 | F18: =(SUMPRODUCT('11 DCF Valuation'!$F$4:$O$4,1/(1+$B18)^'05 Revenue Build'!$F$4:$O$4)+'06 Operating Model'!$O$6*F$15/(1+$B18)^10+'03 Assumptions'!$B$44)/'03 Assumptions'!$B$23 | G18: =(SUMPRODUCT('11 DCF Valuation'!$F$4:$O$4,1/(1+$B18)^'05 Revenue Build'!$F$4:$O$4)+'06 Operating Model'!$O$6*G$15/(1+$B18)^10+'03 Assumptions'!$B$44)/'03 Assumptions'!$B$23 | H18: =(SUMPRODUCT('11 DCF Valuation'!$F$4:$O$4,1/(1+$B18)^'05 Revenue Build'!$F$4:$O$4)+'06 Operating Model'!$O$6*H$15/(1+$B18)^10+'03 Assumptions'!$B$44)/'03 Assumptions'!$B$23
B19: 0.0775 | C19: =(SUMPRODUCT('11 DCF Valuation'!$F$4:$O$4,1/(1+$B19)^'05 Revenue Build'!$F$4:$O$4)+'06 Operating Model'!$O$6*C$15/(1+$B19)^10+'03 Assumptions'!$B$44)/'03 Assumptions'!$B$23 | D19: =(SUMPRODUCT('11 DCF Valuation'!$F$4:$O$4,1/(1+$B19)^'05 Revenue Build'!$F$4:$O$4)+'06 Operating Model'!$O$6*D$15/(1+$B19)^10+'03 Assumptions'!$B$44)/'03 Assumptions'!$B$23 | E19: =(SUMPRODUCT('11 DCF Valuation'!$F$4:$O$4,1/(1+$B19)^'05 Revenue Build'!$F$4:$O$4)+'06 Operating Model'!$O$6*E$15/(1+$B19)^10+'03 Assumptions'!$B$44)/'03 Assumptions'!$B$23 | F19: =(SUMPRODUCT('11 DCF Valuation'!$F$4:$O$4,1/(1+$B19)^'05 Revenue Build'!$F$4:$O$4)+'06 Operating Model'!$O$6*F$15/(1+$B19)^10+'03 Assumptions'!$B$44)/'03 Assumptions'!$B$23 | G19: =(SUMPRODUCT('11 DCF Valuation'!$F$4:$O$4,1/(1+$B19)^'05 Revenue Build'!$F$4:$O$4)+'06 Operating Model'!$O$6*G$15/(1+$B19)^10+'03 Assumptions'!$B$44)/'03 Assumptions'!$B$23 | H19: =(SUMPRODUCT('11 DCF Valuation'!$F$4:$O$4,1/(1+$B19)^'05 Revenue Build'!$F$4:$O$4)+'06 Operating Model'!$O$6*H$15/(1+$B19)^10+'03 Assumptions'!$B$44)/'03 Assumptions'!$B$23
B20: 0.08 | C20: =(SUMPRODUCT('11 DCF Valuation'!$F$4:$O$4,1/(1+$B20)^'05 Revenue Build'!$F$4:$O$4)+'06 Operating Model'!$O$6*C$15/(1+$B20)^10+'03 Assumptions'!$B$44)/'03 Assumptions'!$B$23 | D20: =(SUMPRODUCT('11 DCF Valuation'!$F$4:$O$4,1/(1+$B20)^'05 Revenue Build'!$F$4:$O$4)+'06 Operating Model'!$O$6*D$15/(1+$B20)^10+'03 Assumptions'!$B$44)/'03 Assumptions'!$B$23 | E20: =(SUMPRODUCT('11 DCF Valuation'!$F$4:$O$4,1/(1+$B20)^'05 Revenue Build'!$F$4:$O$4)+'06 Operating Model'!$O$6*E$15/(1+$B20)^10+'03 Assumptions'!$B$44)/'03 Assumptions'!$B$23 | F20: =(SUMPRODUCT('11 DCF Valuation'!$F$4:$O$4,1/(1+$B20)^'05 Revenue Build'!$F$4:$O$4)+'06 Operating Model'!$O$6*F$15/(1+$B20)^10+'03 Assumptions'!$B$44)/'03 Assumptions'!$B$23 | G20: =(SUMPRODUCT('11 DCF Valuation'!$F$4:$O$4,1/(1+$B20)^'05 Revenue Build'!$F$4:$O$4)+'06 Operating Model'!$O$6*G$15/(1+$B20)^10+'03 Assumptions'!$B$44)/'03 Assumptions'!$B$23 | H20: =(SUMPRODUCT('11 DCF Valuation'!$F$4:$O$4,1/(1+$B20)^'05 Revenue Build'!$F$4:$O$4)+'06 Operating Model'!$O$6*H$15/(1+$B20)^10+'03 Assumptions'!$B$44)/'03 Assumptions'!$B$23
B21: 0.085 | C21: =(SUMPRODUCT('11 DCF Valuation'!$F$4:$O$4,1/(1+$B21)^'05 Revenue Build'!$F$4:$O$4)+'06 Operating Model'!$O$6*C$15/(1+$B21)^10+'03 Assumptions'!$B$44)/'03 Assumptions'!$B$23 | D21: =(SUMPRODUCT('11 DCF Valuation'!$F$4:$O$4,1/(1+$B21)^'05 Revenue Build'!$F$4:$O$4)+'06 Operating Model'!$O$6*D$15/(1+$B21)^10+'03 Assumptions'!$B$44)/'03 Assumptions'!$B$23 | E21: =(SUMPRODUCT('11 DCF Valuation'!$F$4:$O$4,1/(1+$B21)^'05 Revenue Build'!$F$4:$O$4)+'06 Operating Model'!$O$6*E$15/(1+$B21)^10+'03 Assumptions'!$B$44)/'03 Assumptions'!$B$23 | F21: =(SUMPRODUCT('11 DCF Valuation'!$F$4:$O$4,1/(1+$B21)^'05 Revenue Build'!$F$4:$O$4)+'06 Operating Model'!$O$6*F$15/(1+$B21)^10+'03 Assumptions'!$B$44)/'03 Assumptions'!$B$23 | G21: =(SUMPRODUCT('11 DCF Valuation'!$F$4:$O$4,1/(1+$B21)^'05 Revenue Build'!$F$4:$O$4)+'06 Operating Model'!$O$6*G$15/(1+$B21)^10+'03 Assumptions'!$B$44)/'03 Assumptions'!$B$23 | H21: =(SUMPRODUCT('11 DCF Valuation'!$F$4:$O$4,1/(1+$B21)^'05 Revenue Build'!$F$4:$O$4)+'06 Operating Model'!$O$6*H$15/(1+$B21)^10+'03 Assumptions'!$B$44)/'03 Assumptions'!$B$23
A24: GRID 3 - EBITDA margin endpoint (rows) x revenue CAGR 2026-35 (cols) - EXACT for stated axes
A25: Engine: Rev_t=1019.3x(1+CAGR)^t; margin linear 21.6% to endpoint by yr7; FCFF=EBITDA(1-t)+t*DA-capex-lease-dNWC; Gordon TV.
C26: 0.03 | D26: 0.05 | E26: 0.07 | F26: 0.09 | G26: 0.11
B27: 0.215 | C27: =(SUMPRODUCT( (1019.3*(1+C$26)^'05 Revenue Build'!$F$4:$O$4) * ( ((0.216+($B27-0.216)*(('05 Revenue Build'!$F$4:$O$4)*('05 Revenue Build'!$F$4:$O$4<=7)+7*('05 Revenue Build'!$F$4:$O$4>7))/7)-'03 Assumptions'!$B$22)*(1-'03 Assumptions'!$B$21) + '03 Assumptions'!$B$22 - '03 Assumptions'!$F$14 - '03 Assumptions'!$B$43 ) / (1+'10 WACC'!$B$15)^'05 Revenue Build'!$F$4:$O$4 )- SUMPRODUCT( '07 Working Capital'!$B$12*1019.3*((1+C$26)^'05 Revenue Build'!$F$4:$O$4-(1+C$26)^('05 Revenue Build'!$F$4:$O$4-1)) / (1+'10 WACC'!$B$15)^'05 Revenue Build'!$F$4:$O$4 )+ (1019.3*(1+C$26)^10*(($B27-'03 Assumptions'!$B$22)*(1-'03 Assumptions'!$B$21)+'03 Assumptions'!$B$22-'03 Assumptions'!$F$14-'03 Assumptions'!$B$43-'07 Working Capital'!$B$12*C$26)*(1+'03 Assumptions'!$F$16)/('10 WACC'!$B$15-'03 Assumptions'!$F$16))/(1+'10 WACC'!$B$15)^10+ '03 Assumptions'!$B$44)/'03 Assumptions'!$B$23 | D27: =(SUMPRODUCT( (1019.3*(1+D$26)^'05 Revenue Build'!$F$4:$O$4) * ( ((0.216+($B27-0.216)*(('05 Revenue Build'!$F$4:$O$4)*('05 Revenue Build'!$F$4:$O$4<=7)+7*('05 Revenue Build'!$F$4:$O$4>7))/7)-'03 Assumptions'!$B$22)*(1-'03 Assumptions'!$B$21) + '03 Assumptions'!$B$22 - '03 Assumptions'!$F$14 - '03 Assumptions'!$B$43 ) / (1+'10 WACC'!$B$15)^'05 Revenue Build'!$F$4:$O$4 )- SUMPRODUCT( '07 Working Capital'!$B$12*1019.3*((1+D$26)^'05 Revenue Build'!$F$4:$O$4-(1+D$26)^('05 Revenue Build'!$F$4:$O$4-1)) / (1+'10 WACC'!$B$15)^'05 Revenue Build'!$F$4:$O$4 )+ (1019.3*(1+D$26)^10*(($B27-'03 Assumptions'!$B$22)*(1-'03 Assumptions'!$B$21)+'03 Assumptions'!$B$22-'03 Assumptions'!$F$14-'03 Assumptions'!$B$43-'07 Working Capital'!$B$12*D$26)*(1+'03 Assumptions'!$F$16)/('10 WACC'!$B$15-'03 Assumptions'!$F$16))/(1+'10 WACC'!$B$15)^10+ '03 Assumptions'!$B$44)/'03 Assumptions'!$B$23 | E27: =(SUMPRODUCT( (1019.3*(1+E$26)^'05 Revenue Build'!$F$4:$O$4) * ( ((0.216+($B27-0.216)*(('05 Revenue Build'!$F$4:$O$4)*('05 Revenue Build'!$F$4:$O$4<=7)+7*('05 Revenue Build'!$F$4:$O$4>7))/7)-'03 Assumptions'!$B$22)*(1-'03 Assumptions'!$B$21) + '03 Assumptions'!$B$22 - '03 Assumptions'!$F$14 - '03 Assumptions'!$B$43 ) / (1+'10 WACC'!$B$15)^'05 Revenue Build'!$F$4:$O$4 )- SUMPRODUCT( '07 Working Capital'!$B$12*1019.3*((1+E$26)^'05 Revenue Build'!$F$4:$O$4-(1+E$26)^('05 Revenue Build'!$F$4:$O$4-1)) / (1+'10 WACC'!$B$15)^'05 Revenue Build'!$F$4:$O$4 )+ (1019.3*(1+E$26)^10*(($B27-'03 Assumptions'!$B$22)*(1-'03 Assumptions'!$B$21)+'03 Assumptions'!$B$22-'03 Assumptions'!$F$14-'03 Assumptions'!$B$43-'07 Working Capital'!$B$12*E$26)*(1+'03 Assumptions'!$F$16)/('10 WACC'!$B$15-'03 Assumptions'!$F$16))/(1+'10 WACC'!$B$15)^10+ '03 Assumptions'!$B$44)/'03 Assumptions'!$B$23 | F27: =(SUMPRODUCT( (1019.3*(1+F$26)^'05 Revenue Build'!$F$4:$O$4) * ( ((0.216+($B27-0.216)*(('05 Revenue Build'!$F$4:$O$4)*('05 Revenue Build'!$F$4:$O$4<=7)+7*('05 Revenue Build'!$F$4:$O$4>7))/7)-'03 Assumptions'!$B$22)*(1-'03 Assumptions'!$B$21) + '03 Assumptions'!$B$22 - '03 Assumptions'!$F$14 - '03 Assumptions'!$B$43 ) / (1+'10 WACC'!$B$15)^'05 Revenue Build'!$F$4:$O$4 )- SUMPRODUCT( '07 Working Capital'!$B$12*1019.3*((1+F$26)^'05 Revenue Build'!$F$4:$O$4-(1+F$26)^('05 Revenue Build'!$F$4:$O$4-1)) / (1+'10 WACC'!$B$15)^'05 Revenue Build'!$F$4:$O$4 )+ (1019.3*(1+F$26)^10*(($B27-'03 Assumptions'!$B$22)*(1-'03 Assumptions'!$B$21)+'03 Assumptions'!$B$22-'03 Assumptions'!$F$14-'03 Assumptions'!$B$43-'07 Working Capital'!$B$12*F$26)*(1+'03 Assumptions'!$F$16)/('10 WACC'!$B$15-'03 Assumptions'!$F$16))/(1+'10 WACC'!$B$15)^10+ '03 Assumptions'!$B$44)/'03 Assumptions'!$B$23 | G27: =(SUMPRODUCT( (1019.3*(1+G$26)^'05 Revenue Build'!$F$4:$O$4) * ( ((0.216+($B27-0.216)*(('05 Revenue Build'!$F$4:$O$4)*('05 Revenue Build'!$F$4:$O$4<=7)+7*('05 Revenue Build'!$F$4:$O$4>7))/7)-'03 Assumptions'!$B$22)*(1-'03 Assumptions'!$B$21) + '03 Assumptions'!$B$22 - '03 Assumptions'!$F$14 - '03 Assumptions'!$B$43 ) / (1+'10 WACC'!$B$15)^'05 Revenue Build'!$F$4:$O$4 )- SUMPRODUCT( '07 Working Capital'!$B$12*1019.3*((1+G$26)^'05 Revenue Build'!$F$4:$O$4-(1+G$26)^('05 Revenue Build'!$F$4:$O$4-1)) / (1+'10 WACC'!$B$15)^'05 Revenue Build'!$F$4:$O$4 )+ (1019.3*(1+G$26)^10*(($B27-'03 Assumptions'!$B$22)*(1-'03 Assumptions'!$B$21)+'03 Assumptions'!$B$22-'03 Assumptions'!$F$14-'03 Assumptions'!$B$43-'07 Working Capital'!$B$12*G$26)*(1+'03 Assumptions'!$F$16)/('10 WACC'!$B$15-'03 Assumptions'!$F$16))/(1+'10 WACC'!$B$15)^10+ '03 Assumptions'!$B$44)/'03 Assumptions'!$B$23
B28: 0.225 | C28: =(SUMPRODUCT( (1019.3*(1+C$26)^'05 Revenue Build'!$F$4:$O$4) * ( ((0.216+($B28-0.216)*(('05 Revenue Build'!$F$4:$O$4)*('05 Revenue Build'!$F$4:$O$4<=7)+7*('05 Revenue Build'!$F$4:$O$4>7))/7)-'03 Assumptions'!$B$22)*(1-'03 Assumptions'!$B$21) + '03 Assumptions'!$B$22 - '03 Assumptions'!$F$14 - '03 Assumptions'!$B$43 ) / (1+'10 WACC'!$B$15)^'05 Revenue Build'!$F$4:$O$4 )- SUMPRODUCT( '07 Working Capital'!$B$12*1019.3*((1+C$26)^'05 Revenue Build'!$F$4:$O$4-(1+C$26)^('05 Revenue Build'!$F$4:$O$4-1)) / (1+'10 WACC'!$B$15)^'05 Revenue Build'!$F$4:$O$4 )+ (1019.3*(1+C$26)^10*(($B28-'03 Assumptions'!$B$22)*(1-'03 Assumptions'!$B$21)+'03 Assumptions'!$B$22-'03 Assumptions'!$F$14-'03 Assumptions'!$B$43-'07 Working Capital'!$B$12*C$26)*(1+'03 Assumptions'!$F$16)/('10 WACC'!$B$15-'03 Assumptions'!$F$16))/(1+'10 WACC'!$B$15)^10+ '03 Assumptions'!$B$44)/'03 Assumptions'!$B$23 | D28: =(SUMPRODUCT( (1019.3*(1+D$26)^'05 Revenue Build'!$F$4:$O$4) * ( ((0.216+($B28-0.216)*(('05 Revenue Build'!$F$4:$O$4)*('05 Revenue Build'!$F$4:$O$4<=7)+7*('05 Revenue Build'!$F$4:$O$4>7))/7)-'03 Assumptions'!$B$22)*(1-'03 Assumptions'!$B$21) + '03 Assumptions'!$B$22 - '03 Assumptions'!$F$14 - '03 Assumptions'!$B$43 ) / (1+'10 WACC'!$B$15)^'05 Revenue Build'!$F$4:$O$4 )- SUMPRODUCT( '07 Working Capital'!$B$12*1019.3*((1+D$26)^'05 Revenue Build'!$F$4:$O$4-(1+D$26)^('05 Revenue Build'!$F$4:$O$4-1)) / (1+'10 WACC'!$B$15)^'05 Revenue Build'!$F$4:$O$4 )+ (1019.3*(1+D$26)^10*(($B28-'03 Assumptions'!$B$22)*(1-'03 Assumptions'!$B$21)+'03 Assumptions'!$B$22-'03 Assumptions'!$F$14-'03 Assumptions'!$B$43-'07 Working Capital'!$B$12*D$26)*(1+'03 Assumptions'!$F$16)/('10 WACC'!$B$15-'03 Assumptions'!$F$16))/(1+'10 WACC'!$B$15)^10+ '03 Assumptions'!$B$44)/'03 Assumptions'!$B$23 | E28: =(SUMPRODUCT( (1019.3*(1+E$26)^'05 Revenue Build'!$F$4:$O$4) * ( ((0.216+($B28-0.216)*(('05 Revenue Build'!$F$4:$O$4)*('05 Revenue Build'!$F$4:$O$4<=7)+7*('05 Revenue Build'!$F$4:$O$4>7))/7)-'03 Assumptions'!$B$22)*(1-'03 Assumptions'!$B$21) + '03 Assumptions'!$B$22 - '03 Assumptions'!$F$14 - '03 Assumptions'!$B$43 ) / (1+'10 WACC'!$B$15)^'05 Revenue Build'!$F$4:$O$4 )- SUMPRODUCT( '07 Working Capital'!$B$12*1019.3*((1+E$26)^'05 Revenue Build'!$F$4:$O$4-(1+E$26)^('05 Revenue Build'!$F$4:$O$4-1)) / (1+'10 WACC'!$B$15)^'05 Revenue Build'!$F$4:$O$4 )+ (1019.3*(1+E$26)^10*(($B28-'03 Assumptions'!$B$22)*(1-'03 Assumptions'!$B$21)+'03 Assumptions'!$B$22-'03 Assumptions'!$F$14-'03 Assumptions'!$B$43-'07 Working Capital'!$B$12*E$26)*(1+'03 Assumptions'!$F$16)/('10 WACC'!$B$15-'03 Assumptions'!$F$16))/(1+'10 WACC'!$B$15)^10+ '03 Assumptions'!$B$44)/'03 Assumptions'!$B$23 | F28: =(SUMPRODUCT( (1019.3*(1+F$26)^'05 Revenue Build'!$F$4:$O$4) * ( ((0.216+($B28-0.216)*(('05 Revenue Build'!$F$4:$O$4)*('05 Revenue Build'!$F$4:$O$4<=7)+7*('05 Revenue Build'!$F$4:$O$4>7))/7)-'03 Assumptions'!$B$22)*(1-'03 Assumptions'!$B$21) + '03 Assumptions'!$B$22 - '03 Assumptions'!$F$14 - '03 Assumptions'!$B$43 ) / (1+'10 WACC'!$B$15)^'05 Revenue Build'!$F$4:$O$4 )- SUMPRODUCT( '07 Working Capital'!$B$12*1019.3*((1+F$26)^'05 Revenue Build'!$F$4:$O$4-(1+F$26)^('05 Revenue Build'!$F$4:$O$4-1)) / (1+'10 WACC'!$B$15)^'05 Revenue Build'!$F$4:$O$4 )+ (1019.3*(1+F$26)^10*(($B28-'03 Assumptions'!$B$22)*(1-'03 Assumptions'!$B$21)+'03 Assumptions'!$B$22-'03 Assumptions'!$F$14-'03 Assumptions'!$B$43-'07 Working Capital'!$B$12*F$26)*(1+'03 Assumptions'!$F$16)/('10 WACC'!$B$15-'03 Assumptions'!$F$16))/(1+'10 WACC'!$B$15)^10+ '03 Assumptions'!$B$44)/'03 Assumptions'!$B$23 | G28: =(SUMPRODUCT( (1019.3*(1+G$26)^'05 Revenue Build'!$F$4:$O$4) * ( ((0.216+($B28-0.216)*(('05 Revenue Build'!$F$4:$O$4)*('05 Revenue Build'!$F$4:$O$4<=7)+7*('05 Revenue Build'!$F$4:$O$4>7))/7)-'03 Assumptions'!$B$22)*(1-'03 Assumptions'!$B$21) + '03 Assumptions'!$B$22 - '03 Assumptions'!$F$14 - '03 Assumptions'!$B$43 ) / (1+'10 WACC'!$B$15)^'05 Revenue Build'!$F$4:$O$4 )- SUMPRODUCT( '07 Working Capital'!$B$12*1019.3*((1+G$26)^'05 Revenue Build'!$F$4:$O$4-(1+G$26)^('05 Revenue Build'!$F$4:$O$4-1)) / (1+'10 WACC'!$B$15)^'05 Revenue Build'!$F$4:$O$4 )+ (1019.3*(1+G$26)^10*(($B28-'03 Assumptions'!$B$22)*(1-'03 Assumptions'!$B$21)+'03 Assumptions'!$B$22-'03 Assumptions'!$F$14-'03 Assumptions'!$B$43-'07 Working Capital'!$B$12*G$26)*(1+'03 Assumptions'!$F$16)/('10 WACC'!$B$15-'03 Assumptions'!$F$16))/(1+'10 WACC'!$B$15)^10+ '03 Assumptions'!$B$44)/'03 Assumptions'!$B$23
